Workbook
Name _1_200_CTCONTROL_PROY: '[1]202 TCONTROL_TOTAL_PROY'!#REF!
Name codestado: [2]!Tabla6[Código]
Name codmes: [2]!Tabla7[Código]
Name codrec: [2]!Tabla5[Código]
Name codselec: [2]!Modalidades[Código]
Name codvigencias: [2]!Tabla8[¿Se requieren vigencias futuras?]
Name DEPENDENCIA: '[3]Anexo 2.'!$B$416:$B$441
Name estado: [2]!Tabla6[Estado de solicitud de vigencias futuras]
Name EstadoContrato: '[3]Anexo 2.'!$B$446:$B$452
Name FUENTE: '[3]Anexo 2.'!$D$449:$D$453
Name gobernacion: '[4]Anexo 2.'!$D$391:$D$394
Name intervalos: [2]!Tabla4[Duración estimada del contrato (intervalo: días, meses, años)]
Name l: '[5]Anexo 2.'!$D$357:$D$387
Name ll: '[5]Anexo 2.'!$D$357:$D$387
Name meses: [2]!Tabla7[Mes]
Name MODALIDAD: '[6]Anexo 2.'!$D$322:$D$349
Name modselec: [2]!Modalidades[[Modalidad de selección ]]
Name MODSELECCION: '[3]Anexo 2.'!$D$416:$D$446
Name MUJERES: '[7]Anexo 2.'!$B$319:$B$344
Name Municipios: Table1[]
Name Municipios: Table1[#Data]
Name Municipios: Table1[]
Name Municipios: Table1[]
Name NECESIDAD: '2.BDN (backup)'!$B$2:$U$330
Name NECESIDAD: #REF!
Name NECESIDAD: '2.BDN'!$B$2:$P$327
Name Nombproducto: [8]!Articulacion[NOMBRE PRODUCTO]
Name NombPrograma: [8]!Articulacion[NOMBRE PROGRAMA]
Name Nombproyecto: [8]!Articulacion[NOMBRE PROYECTO]
Name PEP: [8]!Articulacion[ELEMENTO PEP]
Name PROGRAMAS: '[3]Anexo 2.'!$F$423:$F$551
Name recursos: [2]!Tabla5[Fuente de los recursos]
Name secretaira: '[4]Anexo 2.'!$B$351:$B$376
Name TIPOSUPER: '[9]Anexo 2.'!$F$579:$F$583
Name VIGENCIAS: '[10]Anexo 2.'!$E$404:$E$407

Sheet 1.RADICADOS
A1: ID_RADICADOS | B1: RADICADO | C1: FECHA | D1: DIAS TRANSCURRIDOS | E1: SUBREGIÓN (BLOQUEAR) | F1: MUNICIPIO | G1: ID PROYECTOS | H1: PROYECTOS | I1: TIPO DE SOLICITUD | J1: PRESUPUESTO (ELIMINAR) | K1: OBSERVACIONES
A2: =ROW() - ROW(radicados[[#Headers],[ID_RADICADOS]]) -> 1 | B2: 2024010048235 | C2: 45327 | D2: =+TODAY()-radicados[[#This Row],[FECHA]] -> 669 | E2: =+_xlfn.XLOOKUP(radicados[[#This Row],[MUNICIPIO]],MUNICIPIOS!A:A,MUNICIPIOS!E:E,0,0,1) -> Nordeste | F2: Vegachí | G2: 1 | H2: CONSTRUCCIÓN DE PARQUES DEL RIO, ETAPA 1, EN EL MUNICIPIO DE VEGACHÍ, ANTIOQUIA” | I2: Ajuste proyecto | J2: 666322545
A3: =ROW() - ROW(radicados[[#Headers],[ID_RADICADOS]]) -> 2 | B3: 2024010031666 | C3: 45316 | D3: =+TODAY()-radicados[[#This Row],[FECHA]] -> 680 | E3: =+_xlfn.XLOOKUP(radicados[[#This Row],[MUNICIPIO]],MUNICIPIOS!A:A,MUNICIPIOS!E:E,0,0,1) -> Magdalena Medio | F3: Puerto Triunfo | G3: 2 | H3: Construcción de muelle Malecón turístico en la Cabecera municipal de Puerto Triunfo Antioquia | I3: Ajuste proyecto | J3: 496406918
A4: =ROW() - ROW(radicados[[#Headers],[ID_RADICADOS]]) -> 3 | B4: 2024010111694 | C4: 45629 | D4: =+TODAY()-radicados[[#This Row],[FECHA]] -> 367 | E4: =+_xlfn.XLOOKUP(radicados[[#This Row],[MUNICIPIO]],MUNICIPIOS!A:A,MUNICIPIOS!E:E,0,0,1) -> Valle de Aburrá | F4: Barbosa | G4: 3 | H4: Intercambio vial sector 3 | I4: Proyecto nuevo | J4: 54654511129
A5: =ROW() - ROW(radicados[[#Headers],[ID_RADICADOS]]) -> 4 | B5: 2024010110440 | C5: 45599 | D5: =+TODAY()-radicados[[#This Row],[FECHA]] -> 397 | E5: =+_xlfn.XLOOKUP(radicados[[#This Row],[MUNICIPIO]],MUNICIPIOS!A:A,MUNICIPIOS!E:E,0,0,1) -> Oriente | F5: El Retiro | G5: 145 | H5: Parque lineal, Bosques urbanos | I5: Proyecto nuevo | J5: 20074758933
A6: =ROW() - ROW(radicados[[#Headers],[ID_RADICADOS]]) -> 5 | B6: 2024010118992 | C6: 45366 | D6: =+TODAY()-radicados[[#This Row],[FECHA]] -> 630 | E6: =+_xlfn.XLOOKUP(radicados[[#This Row],[MUNICIPIO]],MUNICIPIOS!A:A,MUNICIPIOS!E:E,0,0,1) -> Suroeste | F6: Urrao | G6: 109 | H6: Construcción de pavimento rígido en vías urbanas y rurales del municipio de Urrao | I6: Proyecto nuevo | J6: 0
A7: =ROW() - ROW(radicados[[#Headers],[ID_RADICADOS]]) -> 6 | B7: 2024010105045 | C7: 45476 | D7: =+TODAY()-radicados[[#This Row],[FECHA]] -> 520 | E7: =+_xlfn.XLOOKUP(radicados[[#This Row],[MUNICIPIO]],MUNICIPIOS!A:A,MUNICIPIOS!E:E,0,0,1) -> Oriente | F7: Rionegro | G7: 4 | H7: Construcción del Puente Biblioteca en el municipio de Rionegro | I7: Ajuste proyecto | J7: 8594513471
A8: =ROW() - ROW(radicados[[#Headers],[ID_RADICADOS]]) -> 7 | B8: 2024010070587 | C8: 45338 | D8: =+TODAY()-radicados[[#This Row],[FECHA]] -> 658 | E8: =+_xlfn.XLOOKUP(radicados[[#This Row],[MUNICIPIO]],MUNICIPIOS!A:A,MUNICIPIOS!E:E,0,0,1) -> Suroeste | F8: Santa Bárbara | G8: 5 | H8: Pavimentación de la vía Santa Bárbara - Fredonia (ruta 25) Fredonia Código 25AN02 en el Plan de Desarrollo Departamental 2024 - 2027 | I8: Proyecto nuevo | J8: 0
A9: =ROW() - ROW(radicados[[#Headers],[ID_RADICADOS]]) -> 8 | B9: 2024010071479 | C9: 45341 | D9: =+TODAY()-radicados[[#This Row],[FECHA]] -> 655 | E9: =+_xlfn.XLOOKUP(radicados[[#This Row],[MUNICIPIO]],MUNICIPIOS!A:A,MUNICIPIOS!E:E,0,0,1) -> Oriente | F9: Abejorral | G9: 6 | H9: Placa huella Abejorral - Purima | I9: Proyecto nuevo | J9: 6800000000
A10: =ROW() - ROW(radicados[[#Headers],[ID_RADICADOS]]) -> 9 | B10: 2024010019030 | C10: 45308 | D10: =+TODAY()-radicados[[#This Row],[FECHA]] -> 688 | E10: =+_xlfn.XLOOKUP(radicados[[#This Row],[MUNICIPIO]],MUNICIPIOS!A:A,MUNICIPIOS!E:E,0,0,1) -> Norte | F10: Donmatías | G10: 7 | H10: Pavimentación de 11km de la vía Riogrande - Bellavista (05237VT073) | I10: Proyecto nuevo | J10: 0
A11: =ROW() - ROW(radicados[[#Headers],[ID_RADICADOS]]) -> 10 | B11: 2024010020020 | C11: 45308 | D11: =+TODAY()-radicados[[#This Row],[FECHA]] -> 688 | E11: =+_xlfn.XLOOKUP(radicados[[#This Row],[MUNICIPIO]],MUNICIPIOS!A:A,MUNICIPIOS!E:E,0,0,1) -> Urabá | F11: Carepa | G11: 8 | H11: Solicitud de apoyo y acompañamiento integral a la Gestión territorial - Remitido por el ministerio de ambiente | J11: 0
A12: =ROW() - ROW(radicados[[#Headers],[ID_RADICADOS]]) -> 11 | B12: 2024010048752 | C12: 45414 | D12: =+TODAY()-radicados[[#This Row],[FECHA]] -> 582 | E12: =+_xlfn.XLOOKUP(radicados[[#This Row],[MUNICIPIO]],MUNICIPIOS!A:A,MUNICIPIOS!E:E,0,0,1) -> Nordeste | F12: Vegachí | G12: 9 | H12: Pavimentación de la vía que conduce al corregimiento portachuelo en Amalfí desde el municipio de Vegachí (05858VT61) "Alejandría - Cascajo" | I12: Proyecto nuevo | J12: 0
A13: =ROW() - ROW(radicados[[#Headers],[ID_RADICADOS]]) -> 12 | B13: 2024010043395 | C13: 45293 | D13: =+TODAY()-radicados[[#This Row],[FECHA]] -> 703 | E13: =+_xlfn.XLOOKUP(radicados[[#This Row],[MUNICIPIO]],MUNICIPIOS!A:A,MUNICIPIOS!E:E,0,0,1) -> Bajo Cauca | F13: Caucasia | G13: 10 | H13: Aeropuerto Regional - Parque Lineal (Ciclo vía) - Peopuesta proyectos en desarrollo Bajo Cauca Antioqueño. Finca la Mariela - Caucasía, Antioquia | I13: Proyecto nuevo | J13: 0
A14: =ROW() - ROW(radicados[[#Headers],[ID_RADICADOS]]) -> 13 | B14: 2024010068835 | C14: 45338 | D14: =+TODAY()-radicados[[#This Row],[FECHA]] -> 658 | E14: =+_xlfn.XLOOKUP(radicados[[#This Row],[MUNICIPIO]],MUNICIPIOS!A:A,MUNICIPIOS!E:E,0,0,1) -> Occidente | F14: Armenia | G14: 11 | H14: Recuperación, pavimentación y mantenimiento a la malla vial que comunica al municipio de Armenia con el municipio de Titiribí | J14: 0
A15: =ROW() - ROW(radicados[[#Headers],[ID_RADICADOS]]) -> 14 | B15: 2024010033632 | C15: 45316 | D15: =+TODAY()-radicados[[#This Row],[FECHA]] -> 680 | E15: =+_xlfn.XLOOKUP(radicados[[#This Row],[MUNICIPIO]],MUNICIPIOS!A:A,MUNICIPIOS!E:E,0,0,1) -> 0 | G15: 12 | H15: Incluir el plan de negocios del PTI, en el plan de Desarrollo de Antioquia Firme financiación para la terminación de los estudios de la pre-factibilidad y el acompañamiento del lincenciamiento ante la ANI. | I15: Petición | J15: 0
A16: =ROW() - ROW(radicados[[#Headers],[ID_RADICADOS]]) -> 15 | B16: 2024010078784 | C16: 45344 | D16: =+TODAY()-radicados[[#This Row],[FECHA]] -> 652 | E16: =+_xlfn.XLOOKUP(radicados[[#This Row],[MUNICIPIO]],MUNICIPIOS!A:A,MUNICIPIOS!E:E,0,0,1) -> Suroeste | F16: Támesis | G16: 54 | H16: Vía entre corregimiento de San Pablo y vereda Naranjal (Codigo 05856VT104) | I16: Proyecto nuevo | J16: 0
A17: =ROW() - ROW(radicados[[#Headers],[ID_RADICADOS]]) -> 16 | B17: 2024010084216 | C17: 45348 | D17: =+TODAY()-radicados[[#This Row],[FECHA]] -> 648 | E17: =+_xlfn.XLOOKUP(radicados[[#This Row],[MUNICIPIO]],MUNICIPIOS!A:A,MUNICIPIOS!E:E,0,0,1) -> Suroeste | F17: Tarso | G17: 14 | H17: Solicitud de Pavimentación vía Peñalisa - La Bodega - Tarso, La Bodega - Pueblorico con codigo 25BAN03-1 | I17: Petición | J17: 51682398
A18: =ROW() - ROW(radicados[[#Headers],[ID_RADICADOS]]) -> 17 | B18: 2024010041849 | C18: 45322 | D18: =+TODAY()-radicados[[#This Row],[FECHA]] -> 674 | E18: =+_xlfn.XLOOKUP(radicados[[#This Row],[MUNICIPIO]],MUNICIPIOS!A:A,MUNICIPIOS!E:E,0,0,1) -> Norte | F18: San José de la Montaña | G18: 15 | H18: Mejoramiento de la red vial urbana Municipio de San josé de la Montaña | I18: Ajuste proyecto | J18: 294694981
A19: =ROW() - ROW(radicados[[#Headers],[ID_RADICADOS]]) -> 18 | B19: 2024010054228 | C19: 45475 | D19: =+TODAY()-radicados[[#This Row],[FECHA]] -> 521 | E19: =+_xlfn.XLOOKUP(radicados[[#This Row],[MUNICIPIO]],MUNICIPIOS!A:A,MUNICIPIOS!E:E,0,0,1) -> Norte | F19: San José de la Montaña | G19: 16 | H19: Mejoramiento de vías rurales en los municipios de Belmira y San José de la Montaña, Antioquia | I19: Proyecto nuevo | J19: 3142000000
A20: =ROW() - ROW(radicados[[#Headers],[ID_RADICADOS]]) -> 19 | B20: 2024010013378 | C20: 45306 | D20: =+TODAY()-radicados[[#This Row],[FECHA]] -> 690 | E20: =+_xlfn.XLOOKUP(radicados[[#This Row],[MUNICIPIO]],MUNICIPIOS!A:A,MUNICIPIOS!E:E,0,0,1) -> Suroeste | F20: Fredonia | G20: 17 | H20: Solicitud pavimentación vía corregimiento Marsella | I20: Proyecto nuevo | J20: 0
A21: =ROW() - ROW(radicados[[#Headers],[ID_RADICADOS]]) -> 20 | B21: 2024010179553 | C21: 45406 | D21: =+TODAY()-radicados[[#This Row],[FECHA]] -> 590 | E21: =+_xlfn.XLOOKUP(radicados[[#This Row],[MUNICIPIO]],MUNICIPIOS!A:A,MUNICIPIOS!E:E,0,0,1) -> Urabá | F21: San Pedro de Urabá | G21: 18 | H21: Construcción de pavimento rígido en vías del casco urbano del municipio de San Pedro de Urabá, Antiquia | I21: Proyecto nuevo | J21: 0
A22: =ROW() - ROW(radicados[[#Headers],[ID_RADICADOS]]) -> 21 | B22: 2024010178436 | C22: 45405 | D22: =+TODAY()-radicados[[#This Row],[FECHA]] -> 591 | E22: =+_xlfn.XLOOKUP(radicados[[#This Row],[MUNICIPIO]],MUNICIPIOS!A:A,MUNICIPIOS!E:E,0,0,1) -> Urabá | F22: San Juan de Urabá | G22: 19 | H22: Construcción de placa huella en la vía acceso al corregimiento de Belén Municipio de San Juan de Urabá, Antioquia | I22: Proyecto nuevo | J22: 2139964660
A23: =ROW() - ROW(radicados[[#Headers],[ID_RADICADOS]]) -> 22 | B23: 2024010178733 | C23: 45405 | D23: =+TODAY()-radicados[[#This Row],[FECHA]] -> 591 | E23: =+_xlfn.XLOOKUP(radicados[[#This Row],[MUNICIPIO]],MUNICIPIOS!A:A,MUNICIPIOS!E:E,0,0,1) -> Nordeste | F23: Yolombó | G23: 20 | H23: Mejoramiento vías urbanas municipio de Yolombó | I23: Ajuste proyecto | J23: 750000000
A24: =ROW() - ROW(radicados[[#Headers],[ID_RADICADOS]]) -> 23 | B24: 2024020016404 | C24: 45398 | D24: =+TODAY()-radicados[[#This Row],[FECHA]] -> 598 | E24: =+_xlfn.XLOOKUP(radicados[[#This Row],[MUNICIPIO]],MUNICIPIOS!A:A,MUNICIPIOS!E:E,0,0,1) -> Oriente | F24: Rionegro | G24: 21 | H24: Construcción del ámbito patrimonio del proyecto Paisajes del Agua en el Municipio de Rionegro | I24: Ajuste proyecto | J24: 1578945342
A25: =ROW() - ROW(radicados[[#Headers],[ID_RADICADOS]]) -> 24 | B25: 2024010171235 | C25: 45400 | D25: =+TODAY()-radicados[[#This Row],[FECHA]] -> 596 | E25: =+_xlfn.XLOOKUP(radicados[[#This Row],[MUNICIPIO]],MUNICIPIOS!A:A,MUNICIPIOS!E:E,0,0,1) -> Oriente | F25: Alejandría | G25: 22 | H25: Estudios y diseños para plaza de feria ganadera en el municipio de Alejandría - Antioquia | I25: Proyecto nuevo | J25: 112000000
A26: =ROW() - ROW(radicados[[#Headers],[ID_RADICADOS]]) -> 25 | B26: 2024010153392 | C26: 45569 | D26: =+TODAY()-radicados[[#This Row],[FECHA]] -> 427 | E26: =+_xlfn.XLOOKUP(radicados[[#This Row],[MUNICIPIO]],MUNICIPIOS!A:A,MUNICIPIOS!E:E,0,0,1) -> Norte | F26: Donmatías | G26: 23 | H26: Construcción del espacio público parques de la quebrada Donmatías, Antioquia - Etapa 1 | I26: Ajuste proyecto | J26: 764624487
A27: =ROW() - ROW(radicados[[#Headers],[ID_RADICADOS]]) -> 26 | B27: 2024010207402 | C27: 45509 | D27: =+TODAY()-radicados[[#This Row],[FECHA]] -> 487 | E27: =+_xlfn.XLOOKUP(radicados[[#This Row],[MUNICIPIO]],MUNICIPIOS!A:A,MUNICIPIOS!E:E,0,0,1) -> Urabá | F27: Turbo | G27: 24 | H27: Construcción de la fase dos del malecón turístico del Distrito de Turbo | I27: Proyecto nuevo | J27: 0
... A57: =ROW() - ROW(radicados[[#Headers],[ID_RADICADOS]]) -> 56 | B57: 2024010308857 | C57: 45633 | D57: =+TODAY()-radicados[[#This Row],[FECHA]] -> 363 | E57: =+_xlfn.XLOOKUP(radicados[[#This Row],[MUNICIPIO]],MUNICIPIOS!A:A,MUNICIPIOS!E:E,0,0,1) -> Urabá | F57: Chigorodó | G57: 51 | H57: Pavimentación en concreto rígido , andenes peatonales y silvicultura en la calle 97 entre carrera 101 y 112 del municipio de Chigorodó, Antioquia | I57: Proyecto nuevo | J57: 4215630027
A58: =ROW() - ROW(radicados[[#Headers],[ID_RADICADOS]]) -> 57 | B58: 2024010313514 | C58: 45358 | D58: =+TODAY()-radicados[[#This Row],[FECHA]] -> 638 | E58: =+_xlfn.XLOOKUP(radicados[[#This Row],[MUNICIPIO]],MUNICIPIOS!A:A,MUNICIPIOS!E:E,0,0,1) -> Norte | F58: Yarumal | G58: 52 | H58: Intervención de la vía terciaria de acceso al corregimiento cedeño y sus veredas aledañas en el municipio de Yarumal, Antioquia afectada por la ola invernal | J58: 0
A59: =ROW() - ROW(radicados[[#Headers],[ID_RADICADOS]]) -> 58 | B59: 2024010295409 | C59: 45603 | D59: =+TODAY()-radicados[[#This Row],[FECHA]] -> 393 | E59: =+_xlfn.XLOOKUP(radicados[[#This Row],[MUNICIPIO]],MUNICIPIOS!A:A,MUNICIPIOS!E:E,0,0,1) -> Occidente | F59: Sopetrán | G59: 53 | H59: Solicitud de pavimentación de vía Belmira Horizontes | I59: Petición | J59: 0
A60: =ROW() - ROW(radicados[[#Headers],[ID_RADICADOS]]) -> 59 | B60: 2024010309743 | C60: 45490 | D60: =+TODAY()-radicados[[#This Row],[FECHA]] -> 506 | E60: =+_xlfn.XLOOKUP(radicados[[#This Row],[MUNICIPIO]],MUNICIPIOS!A:A,MUNICIPIOS!E:E,0,0,1) -> Suroeste | F60: Támesis | G60: 54 | H60: Construcción de placa huella y obras complementarias en la vía Támesis - San Pablo en el municipio de Támesis - Antioquia | I60: Proyecto nuevo | J60: 3539562399
A61: =ROW() - ROW(radicados[[#Headers],[ID_RADICADOS]]) -> 60 | B61: 2024010319437 | C61: 45634 | D61: =+TODAY()-radicados[[#This Row],[FECHA]] -> 362 | E61: =+_xlfn.XLOOKUP(radicados[[#This Row],[MUNICIPIO]],MUNICIPIOS!A:A,MUNICIPIOS!E:E,0,0,1) -> Oriente | F61: Sonsón | G61: 55 | H61: Pavimentación de 700 metros de pavimento rígido en la vía La Danta - Autopista Medellín - Bogotá | I61: Proyecto nuevo | J61: 684345500
A62: =ROW() - ROW(radicados[[#Headers],[ID_RADICADOS]]) -> 61 | B62: 2024010361194 | C62: 45634 | D62: =+TODAY()-radicados[[#This Row],[FECHA]] -> 362 | E62: =+_xlfn.XLOOKUP(radicados[[#This Row],[MUNICIPIO]],MUNICIPIOS!A:A,MUNICIPIOS!E:E,0,0,1) -> Oriente | F62: Cocorná | G62: 56 | H62: Mejoramiento del corredor turístico Cocorná - Maria Parda con la construcción de 2.6 km de pavimento rígido, en el municipio de Cocorná, Antioquia ADJUNTO CON CONTRASEÑA | I62: Proyecto nuevo | J62: 0
A63: =ROW() - ROW(radicados[[#Headers],[ID_RADICADOS]]) -> 62 | B63: 2024010361554 | C63: 45504 | D63: =+TODAY()-radicados[[#This Row],[FECHA]] -> 492 | E63: =+_xlfn.XLOOKUP(radicados[[#This Row],[MUNICIPIO]],MUNICIPIOS!A:A,MUNICIPIOS!E:E,0,0,1) -> Suroeste | F63: Betania | G63: 57 | H63: PAVIMENTACIÓN DE VÍAS URBANAS Y OBRAS DE CONTENCIÓN EN EL MUNICIPIO DE BETANIA ANTIOQUIA | I63: Proyecto nuevo | J63: 4172739792
A64: =ROW() - ROW(radicados[[#Headers],[ID_RADICADOS]]) -> 63 | B64: 2024010344153 | C64: 45512 | D64: =+TODAY()-radicados[[#This Row],[FECHA]] -> 484 | E64: =+_xlfn.XLOOKUP(radicados[[#This Row],[MUNICIPIO]],MUNICIPIOS!A:A,MUNICIPIOS!E:E,0,0,1) -> Urabá | F64: Apartadó | G64: 48 | H64: Construcción de pavimento rigido en vias urbanas, Barrio obrero del municipio de Apartadó. | I64: Proyecto nuevo | J64: 7999391717
A65: =ROW() - ROW(radicados[[#Headers],[ID_RADICADOS]]) -> 64 | B65: 2024010356273 | C65: 45451 | D65: =+TODAY()-radicados[[#This Row],[FECHA]] -> 545 | E65: =+_xlfn.XLOOKUP(radicados[[#This Row],[MUNICIPIO]],MUNICIPIOS!A:A,MUNICIPIOS!E:E,0,0,1) -> Urabá | F65: Apartadó | G65: 58 | H65: Mejoramiento de vías terciarias en la vereda Churido Medio, zona rural del municipio de Apartadó, Antioquia. | I65: Proyecto nuevo | J65: 7500000000
A66: =ROW() - ROW(radicados[[#Headers],[ID_RADICADOS]]) -> 65 | B66: 2024010354533 | C66: 45518 | D66: =+TODAY()-radicados[[#This Row],[FECHA]] -> 478 | E66: =+_xlfn.XLOOKUP(radicados[[#This Row],[MUNICIPIO]],MUNICIPIOS!A:A,MUNICIPIOS!E:E,0,0,1) -> Valle de Aburrá | F66: Copacabana | G66: 59 | H66: Pavimentación de 2,2 Km vía Medellín-Bogotá y Vereda Peñolcito | I66: Proyecto nuevo | J66: 5661013100
A67: =ROW() - ROW(radicados[[#Headers],[ID_RADICADOS]]) -> 66 | B67: 2024010366485 | C67: 45451 | D67: =+TODAY()-radicados[[#This Row],[FECHA]] -> 545 | E67: =+_xlfn.XLOOKUP(radicados[[#This Row],[MUNICIPIO]],MUNICIPIOS!A:A,MUNICIPIOS!E:E,0,0,1) -> Occidente | F67: Sopetrán | G67: 60 | H67: REHABILITACIÓN Y MEJORAMIENTO DE 1.5 KILOMETROS DE PAVIMENTACIÓN FLEXIBLE DE VÍA RURAL QUE CONDUCE HACIA LA VEREDA EL RODEO, MUNICIPIO DE SOPETRAN, ANTIOQUIA | I67: Proyecto nuevo | J67: 3468415702
A68: =ROW() - ROW(radicados[[#Headers],[ID_RADICADOS]]) -> 67 | B68: 2024010353885 | C68: 45326 | D68: =+TODAY()-radicados[[#This Row],[FECHA]] -> 670 | E68: =+_xlfn.XLOOKUP(radicados[[#This Row],[MUNICIPIO]],MUNICIPIOS!A:A,MUNICIPIOS!E:E,0,0,1) -> Magdalena Medio | F68: Puerto Nare | G68: 61 | H68: MEJORAMIENTO DE LA RED VIAL URBANA DEL MUNICIO DE PUERTO NARE | I68: Proyecto nuevo | J68: 1500000000
A69: =ROW() - ROW(radicados[[#Headers],[ID_RADICADOS]]) -> 68 | B69: 2024010141962 | C69: 45525 | D69: =+TODAY()-radicados[[#This Row],[FECHA]] -> 471 | E69: =+_xlfn.XLOOKUP(radicados[[#This Row],[MUNICIPIO]],MUNICIPIOS!A:A,MUNICIPIOS!E:E,0,0,1) -> Norte | F69: Briceño | G69: 62 | H69: Mantenimiento de la vía terciaria que comunica la vereda El Roblal y el sector la Ye en el Municipio de Briceño, Antioquia. | I69: Proyecto nuevo | J69: 1104890715
...

Sheet 2.BDN
A1: ID_NECESIDAD | B1: NECESIDAD | C1: FECHA RECEPCION NECESIDAD | D1: MUNICIPIO | E1: SUBREGION | F1: LONGITUD | G1: LATITUD | H1: PDET | I1: ZOMAC | J1: RADICADOS ASOCIADOS | K1: FASE PROYECTO | L1: VALOR NECESIDAD SIF | M1: TIPOLOGIA | N1: ORDEN VIAL | O1: ASOCIACION AL PD | P1: OBSERVACION | Q1: PRIORIZADO | R1: POSIBLE FUENTE FINANCIACION | S1: PROGRAMA | T1: CATEGORÍA | U1: INGRESOS EJECUTADOS 2024 PROYECTADOS 2025 | V1: GASTOS EJECUTADOS 2024 PROYECTADOS 2025 | W1: AHORRO OPERACIONAL | X1: DEUDA IDEA Incluye por desembolsar | Y1: DEUDAS CON OTROS BANCOS Incluye por desembolsar | Z1: SALDO TOTAL DEUDA PROYECTADA | AA1: INDICADOR DE CAPACIDAD LEY 358 DE 1997 | AB1: CAPACIDAD MAXIMA DE ENDEUDAMIENTO AL 100% | AC1: CAPACIDAD MAXIMA DE ENDEUDAMIENTO AL 80% | AD1: CAPACIDAD MAXIMA DE ENDEUDAMIENTO AL 60% | AE1: Deuda del IDEA sobre el total | AF1: INDICADOR LEY 617 | AG1: LÍMITE 617 | AH1: SEMÁFORO | AI1: APORTE GOB | AJ1: SOBRANTE FALTANTE
A2: 1 | B2: CONSTRUCCIÓN DE PARQUES DEL RIO ETAPA 1 EN EL MUNICIPIO DE VEGACHÍ ANTIOQUIA” | C2: =+_xlfn.XLOOKUP(PROYECTOS[[#This Row],[ID_NECESIDAD]],'1.RADICADOS'!G:G,'1.RADICADOS'!C:C,0,0,1)*1 -> 45327 | D2: Vegachí | E2: =+_xlfn.XLOOKUP(PROYECTOS[[#This Row],[MUNICIPIO]],MUNICIPIOS!A:A,MUNICIPIOS!E:E,0,0,1) -> Nordeste | F2: =+_xlfn.XLOOKUP(PROYECTOS[[#This Row],[MUNICIPIO]],MUNICIPIOS!A:A,MUNICIPIOS!F:F,0,0,1) -> -74.798714 | G2: =+_xlfn.XLOOKUP(PROYECTOS[[#This Row],[MUNICIPIO]],MUNICIPIOS!A:A,MUNICIPIOS!G:G,0,0,1) -> 6.773525 | H2: =+_xlfn.XLOOKUP(PROYECTOS[[#This Row],[MUNICIPIO]],MUNICIPIOS!A:A,MUNICIPIOS!B:B,0,0,1) -> 0 | I2: =+_xlfn.XLOOKUP(PROYECTOS[[#This Row],[MUNICIPIO]],MUNICIPIOS!A:A,MUNICIPIOS!C:C,0,0,1) -> 1 | J2: {=_xlfn.TEXTJOIN(" ", TRUE, IF(radicados[ID PROYECTOS]=A2, radicados[RADICADO], ""))} -> 2024010048235 | K2: 1 | M2: Parque | N2: N/A | O2: Espacio público adecuado | T2: =+_xlfn.XLOOKUP(PROYECTOS[[#This Row],[MUNICIPIO]],'4.CAP_ENDMNT'!B:B,'4.CAP_ENDMNT'!C:C,0,0,1) -> 6 | U2: =+_xlfn.XLOOKUP(PROYECTOS[[#This Row],[MUNICIPIO]],'4.CAP_ENDMNT'!B:B,'4.CAP_ENDMNT'!D:D,0,0,1) -> 1.4438256e+10 | V2: =+_xlfn.XLOOKUP(PROYECTOS[[#This Row],[MUNICIPIO]],'4.CAP_ENDMNT'!B:B,'4.CAP_ENDMNT'!E:E,0,0,1) -> 4.6682009e+09 | W2: =+_xlfn.XLOOKUP(PROYECTOS[[#This Row],[MUNICIPIO]],'4.CAP_ENDMNT'!B:B,'4.CAP_ENDMNT'!F:F,0,0,1) -> 9.770055e+09 | X2: =+_xlfn.XLOOKUP(PROYECTOS[[#This Row],[MUNICIPIO]],'4.CAP_ENDMNT'!B:B,'4.CAP_ENDMNT'!G:G,0,0,1) -> 2534414723 | Y2: =+_xlfn.XLOOKUP(PROYECTOS[[#This Row],[MUNICIPIO]],'4.CAP_ENDMNT'!B:B,'4.CAP_ENDMNT'!H:H,0,0,1) -> 0 | Z2: =+_xlfn.XLOOKUP(PROYECTOS[[#This Row],[MUNICIPIO]],'4.CAP_ENDMNT'!B:B,'4.CAP_ENDMNT'!I:I,0,0,1) -> 2534414723 | AA2: =+_xlfn.XLOOKUP(PROYECTOS[[#This Row],[MUNICIPIO]],'4.CAP_ENDMNT'!B:B,'4.CAP_ENDMNT'!J:J,0,0,1) -> 0.17553469 | AB2: =+_xlfn.XLOOKUP(PROYECTOS[[#This Row],[MUNICIPIO]],'4.CAP_ENDMNT'!B:B,'4.CAP_ENDMNT'!K:K,0,0,1) -> 1.1903841e+10 | AC2: =+_xlfn.XLOOKUP(PROYECTOS[[#This Row],[MUNICIPIO]],'4.CAP_ENDMNT'!B:B,'4.CAP_ENDMNT'!L:L,0,0,1) -> 9.523073e+09 | AD2: =+_xlfn.XLOOKUP(PROYECTOS[[#This Row],[MUNICIPIO]],'4.CAP_ENDMNT'!B:B,'4.CAP_ENDMNT'!M:M,0,0,1) -> 7.1423047e+09 | AE2: =+_xlfn.XLOOKUP(PROYECTOS[[#This Row],[MUNICIPIO]],'4.CAP_ENDMNT'!B:B,'4.CAP_ENDMNT'!N:N,0,0,1) -> 1 | AF2: =+_xlfn.XLOOKUP(PROYECTOS[[#This Row],[MUNICIPIO]],'4.CAP_ENDMNT'!B:B,'4.CAP_ENDMNT'!O:O,0,0,1) -> 0.51487078 | AG2: =+_xlfn.XLOOKUP(PROYECTOS[[#This Row],[MUNICIPIO]],'4.CAP_ENDMNT'!B:B,'4.CAP_ENDMNT'!P:P,0,0,1) -> 0.8 | AH2: =+_xlfn.XLOOKUP(PROYECTOS[[#This Row],[MUNICIPIO]],'4.CAP_ENDMNT'!B:B,'4.CAP_ENDMNT'!Q:Q,0,0,1) -> Cumple | AI2: =+_xlfn.XLOOKUP(PROYECTOS[[#This Row],[MUNICIPIO]],'4.CAP_ENDMNT'!B:B,'4.CAP_ENDMNT'!V:V,0,0,1) -> 1.4284609e+09 | AJ2: =+_xlfn.XLOOKUP(PROYECTOS[[#This Row],[MUNICIPIO]],'4.CAP_ENDMNT'!B:B,'4.CAP_ENDMNT'!Y:Y,0,0,1) -> 1.1007549e+09
A3: 3 | B3: Intercambio vial sector 3 | C3: =+_xlfn.XLOOKUP(PROYECTOS[[#This Row],[ID_NECESIDAD]],'1.RADICADOS'!G:G,'1.RADICADOS'!C:C,0,0,1)*1 -> 45629 | D3: Barbosa | E3: =+_xlfn.XLOOKUP(PROYECTOS[[#This Row],[MUNICIPIO]],MUNICIPIOS!A:A,MUNICIPIOS!E:E,0,0,1) -> Valle de Aburrá | F3: =+_xlfn.XLOOKUP(PROYECTOS[[#This Row],[MUNICIPIO]],MUNICIPIOS!A:A,MUNICIPIOS!F:F,0,0,1) -> -75.331627 | G3: =+_xlfn.XLOOKUP(PROYECTOS[[#This Row],[MUNICIPIO]],MUNICIPIOS!A:A,MUNICIPIOS!G:G,0,0,1) -> 6,439195 | H3: =+_xlfn.XLOOKUP(PROYECTOS[[#This Row],[MUNICIPIO]],MUNICIPIOS!A:A,MUNICIPIOS!B:B,0,0,1) -> 0 | I3: =+_xlfn.XLOOKUP(PROYECTOS[[#This Row],[MUNICIPIO]],MUNICIPIOS!A:A,MUNICIPIOS!C:C,0,0,1) -> 0 | J3: {=_xlfn.TEXTJOIN(" ", TRUE, IF(radicados[ID PROYECTOS]=A3, radicados[RADICADO], ""))} -> 2024010111694 | K3: 3 | L3: 54654511129 | M3: Intercambio Vial | N3: Urbana | O3: Vía urbana mejorada | T3: =+_xlfn.XLOOKUP(PROYECTOS[[#This Row],[MUNICIPIO]],'4.CAP_ENDMNT'!B:B,'4.CAP_ENDMNT'!C:C,0,0,1) -> 4 | U3: =+_xlfn.XLOOKUP(PROYECTOS[[#This Row],[MUNICIPIO]],'4.CAP_ENDMNT'!B:B,'4.CAP_ENDMNT'!D:D,0,0,1) -> 5.6592203e+10 | V3: =+_xlfn.XLOOKUP(PROYECTOS[[#This Row],[MUNICIPIO]],'4.CAP_ENDMNT'!B:B,'4.CAP_ENDMNT'!E:E,0,0,1) -> 2.4375973e+10 | W3: =+_xlfn.XLOOKUP(PROYECTOS[[#This Row],[MUNICIPIO]],'4.CAP_ENDMNT'!B:B,'4.CAP_ENDMNT'!F:F,0,0,1) -> 3.2216231e+10 | X3: =+_xlfn.XLOOKUP(PROYECTOS[[#This Row],[MUNICIPIO]],'4.CAP_ENDMNT'!B:B,'4.CAP_ENDMNT'!G:G,0,0,1) -> 0 | Y3: =+_xlfn.XLOOKUP(PROYECTOS[[#This Row],[MUNICIPIO]],'4.CAP_ENDMNT'!B:B,'4.CAP_ENDMNT'!H:H,0,0,1) -> 1.5044963e+10 | Z3: =+_xlfn.XLOOKUP(PROYECTOS[[#This Row],[MUNICIPIO]],'4.CAP_ENDMNT'!B:B,'4.CAP_ENDMNT'!I:I,0,0,1) -> 1.5044963e+10 | AA3: =+_xlfn.XLOOKUP(PROYECTOS[[#This Row],[MUNICIPIO]],'4.CAP_ENDMNT'!B:B,'4.CAP_ENDMNT'!J:J,0,0,1) -> 0.26584869 | AB3: =+_xlfn.XLOOKUP(PROYECTOS[[#This Row],[MUNICIPIO]],'4.CAP_ENDMNT'!B:B,'4.CAP_ENDMNT'!K:K,0,0,1) -> 4.154724e+10 | AC3: =+_xlfn.XLOOKUP(PROYECTOS[[#This Row],[MUNICIPIO]],'4.CAP_ENDMNT'!B:B,'4.CAP_ENDMNT'!L:L,0,0,1) -> 3.3237792e+10 | AD3: =+_xlfn.XLOOKUP(PROYECTOS[[#This Row],[MUNICIPIO]],'4.CAP_ENDMNT'!B:B,'4.CAP_ENDMNT'!M:M,0,0,1) -> 2.4928344e+10 | AE3: =+_xlfn.XLOOKUP(PROYECTOS[[#This Row],[MUNICIPIO]],'4.CAP_ENDMNT'!B:B,'4.CAP_ENDMNT'!N:N,0,0,1) -> 0 | AF3: =+_xlfn.XLOOKUP(PROYECTOS[[#This Row],[MUNICIPIO]],'4.CAP_ENDMNT'!B:B,'4.CAP_ENDMNT'!O:O,0,0,1) -> 0.60385208 | AG3: =+_xlfn.XLOOKUP(PROYECTOS[[#This Row],[MUNICIPIO]],'4.CAP_ENDMNT'!B:B,'4.CAP_ENDMNT'!P:P,0,0,1) -> 0.8 | AH3: =+_xlfn.XLOOKUP(PROYECTOS[[#This Row],[MUNICIPIO]],'4.CAP_ENDMNT'!B:B,'4.CAP_ENDMNT'!Q:Q,0,0,1) -> Cumple | AI3: =+_xlfn.XLOOKUP(PROYECTOS[[#This Row],[MUNICIPIO]],'4.CAP_ENDMNT'!B:B,'4.CAP_ENDMNT'!V:V,0,0,1) -> 4.9856688e+09 | AJ3: =+_xlfn.XLOOKUP(PROYECTOS[[#This Row],[MUNICIPIO]],'4.CAP_ENDMNT'!B:B,'4.CAP_ENDMNT'!Y:Y,0,0,1) -> -3.1357431e+10
A4: 4 | B4: Construcción del Puente Biblioteca en el municipio de Rionegro - ADICION A PROYECTO EN EJECUCION | C4: =+_xlfn.XLOOKUP(PROYECTOS[[#This Row],[ID_NECESIDAD]],'1.RADICADOS'!G:G,'1.RADICADOS'!C:C,0,0,1)*1 -> 45476 | D4: Rionegro | E4: =+_xlfn.XLOOKUP(PROYECTOS[[#This Row],[MUNICIPIO]],MUNICIPIOS!A:A,MUNICIPIOS!E:E,0,0,1) -> Oriente | F4: =+_xlfn.XLOOKUP(PROYECTOS[[#This Row],[MUNICIPIO]],MUNICIPIOS!A:A,MUNICIPIOS!F:F,0,0,1) -> -75.377316 | G4: =+_xlfn.XLOOKUP(PROYECTOS[[#This Row],[MUNICIPIO]],MUNICIPIOS!A:A,MUNICIPIOS!G:G,0,0,1) -> 6,147148 | H4: =+_xlfn.XLOOKUP(PROYECTOS[[#This Row],[MUNICIPIO]],MUNICIPIOS!A:A,MUNICIPIOS!B:B,0,0,1) -> 0 | I4: =+_xlfn.XLOOKUP(PROYECTOS[[#This Row],[MUNICIPIO]],MUNICIPIOS!A:A,MUNICIPIOS!C:C,0,0,1) -> 0 | J4: {=_xlfn.TEXTJOIN(" ", TRUE, IF(radicados[ID PROYECTOS]=A4, radicados[RADICADO], ""))} -> 2024010105045 | K4: 3 | L4: 8594513471 | M4: Edificio Institucional | N4: N/A | O4: Equipamientos construidos | P4: Peticion por recursos para obra adicional | T4: =+_xlfn.XLOOKUP(PROYECTOS[[#This Row],[MUNICIPIO]],'4.CAP_ENDMNT'!B:B,'4.CAP_ENDMNT'!C:C,0,0,1) -> 1 | U4: =+_xlfn.XLOOKUP(PROYECTOS[[#This Row],[MUNICIPIO]],'4.CAP_ENDMNT'!B:B,'4.CAP_ENDMNT'!D:D,0,0,1) -> 5.0123644e+11 | V4: =+_xlfn.XLOOKUP(PROYECTOS[[#This Row],[MUNICIPIO]],'4.CAP_ENDMNT'!B:B,'4.CAP_ENDMNT'!E:E,0,0,1) -> 1.1250202e+11 | W4: =+_xlfn.XLOOKUP(PROYECTOS[[#This Row],[MUNICIPIO]],'4.CAP_ENDMNT'!B:B,'4.CAP_ENDMNT'!F:F,0,0,1) -> 3.8873442e+11 | X4: =+_xlfn.XLOOKUP(PROYECTOS[[#This Row],[MUNICIPIO]],'4.CAP_ENDMNT'!B:B,'4.CAP_ENDMNT'!G:G,0,0,1) -> 85394840514 | Y4: =+_xlfn.XLOOKUP(PROYECTOS[[#This Row],[MUNICIPIO]],'4.CAP_ENDMNT'!B:B,'4.CAP_ENDMNT'!H:H,0,0,1) -> 1.1410989e+11 | Z4: =+_xlfn.XLOOKUP(PROYECTOS[[#This Row],[MUNICIPIO]],'4.CAP_ENDMNT'!B:B,'4.CAP_ENDMNT'!I:I,0,0,1) -> 1.9950473e+11 | AA4: =+_xlfn.XLOOKUP(PROYECTOS[[#This Row],[MUNICIPIO]],'4.CAP_ENDMNT'!B:B,'4.CAP_ENDMNT'!J:J,0,0,1) -> 0.39802519 | AB4: =+_xlfn.XLOOKUP(PROYECTOS[[#This Row],[MUNICIPIO]],'4.CAP_ENDMNT'!B:B,'4.CAP_ENDMNT'!K:K,0,0,1) -> 3.0173171e+11 | AC4: =+_xlfn.XLOOKUP(PROYECTOS[[#This Row],[MUNICIPIO]],'4.CAP_ENDMNT'!B:B,'4.CAP_ENDMNT'!L:L,0,0,1) -> 2.4138537e+11 | AD4: =+_xlfn.XLOOKUP(PROYECTOS[[#This Row],[MUNICIPIO]],'4.CAP_ENDMNT'!B:B,'4.CAP_ENDMNT'!M:M,0,0,1) -> 1.8103903e+11 | AE4: =+_xlfn.XLOOKUP(PROYECTOS[[#This Row],[MUNICIPIO]],'4.CAP_ENDMNT'!B:B,'4.CAP_ENDMNT'!N:N,0,0,1) -> 0.42803417 | AF4: =+_xlfn.XLOOKUP(PROYECTOS[[#This Row],[MUNICIPIO]],'4.CAP_ENDMNT'!B:B,'4.CAP_ENDMNT'!O:O,0,0,1) -> 0.23207277 | AG4: =+_xlfn.XLOOKUP(PROYECTOS[[#This Row],[MUNICIPIO]],'4.CAP_ENDMNT'!B:B,'4.CAP_ENDMNT'!P:P,0,0,1) -> 0.65 | AH4: =+_xlfn.XLOOKUP(PROYECTOS[[#This Row],[MUNICIPIO]],'4.CAP_ENDMNT'!B:B,'4.CAP_ENDMNT'!Q:Q,0,0,1) -> Cumple | AI4: =+_xlfn.XLOOKUP(PROYECTOS[[#This Row],[MUNICIPIO]],'4.CAP_ENDMNT'!B:B,'4.CAP_ENDMNT'!V:V,0,0,1) -> 3.6207806e+10 | AJ4: =+_xlfn.XLOOKUP(PROYECTOS[[#This Row],[MUNICIPIO]],'4.CAP_ENDMNT'!B:B,'4.CAP_ENDMNT'!Y:Y,0,0,1) -> 1.9947085e+11
A5: 5 | B5: Pavimentación de la vía Santa Bárbara - Fredonia (ruta 25) Fredonia Código 25AN02 en el Plan de Desarrollo Departamental 2024 - 2027 | C5: =+_xlfn.XLOOKUP(PROYECTOS[[#This Row],[ID_NECESIDAD]],'1.RADICADOS'!G:G,'1.RADICADOS'!C:C,0,0,1)*1 -> 45338 | D5: Santa Bárbara | E5: =+_xlfn.XLOOKUP(PROYECTOS[[#This Row],[MUNICIPIO]],MUNICIPIOS!A:A,MUNICIPIOS!E:E,0,0,1) -> Suroeste | F5: =+_xlfn.XLOOKUP(PROYECTOS[[#This Row],[MUNICIPIO]],MUNICIPIOS!A:A,MUNICIPIOS!F:F,0,0,1) -> -75.567351 | G5: =+_xlfn.XLOOKUP(PROYECTOS[[#This Row],[MUNICIPIO]],MUNICIPIOS!A:A,MUNICIPIOS!G:G,0,0,1) -> 5,875527 | H5: =+_xlfn.XLOOKUP(PROYECTOS[[#This Row],[MUNICIPIO]],MUNICIPIOS!A:A,MUNICIPIOS!B:B,0,0,1) -> 0 | I5: =+_xlfn.XLOOKUP(PROYECTOS[[#This Row],[MUNICIPIO]],MUNICIPIOS!A:A,MUNICIPIOS!C:C,0,0,1) -> 0 | J5: {=_xlfn.TEXTJOIN(" ", TRUE, IF(radicados[ID PROYECTOS]=A5, radicados[RADICADO], ""))} -> 2024010070587 | K5: 1 | M5: Pavimento Flexible | N5: Segundo Orden | O5: Vías secundarias mejoradas | P5: Solicitud para incluir en PD 2024 pavimentacion de via secundaria Santa Barbara - Fredonia | T5: =+_xlfn.XLOOKUP(PROYECTOS[[#This Row],[MUNICIPIO]],'4.CAP_ENDMNT'!B:B,'4.CAP_ENDMNT'!C:C,0,0,1) -> 6 | U5: =+_xlfn.XLOOKUP(PROYECTOS[[#This Row],[MUNICIPIO]],'4.CAP_ENDMNT'!B:B,'4.CAP_ENDMNT'!D:D,0,0,1) -> 1.2109127e+10 | V5: =+_xlfn.XLOOKUP(PROYECTOS[[#This Row],[MUNICIPIO]],'4.CAP_ENDMNT'!B:B,'4.CAP_ENDMNT'!E:E,0,0,1) -> 6.4850763e+09 | W5: =+_xlfn.XLOOKUP(PROYECTOS[[#This Row],[MUNICIPIO]],'4.CAP_ENDMNT'!B:B,'4.CAP_ENDMNT'!F:F,0,0,1) -> 5.624051e+09 | X5: =+_xlfn.XLOOKUP(PROYECTOS[[#This Row],[MUNICIPIO]],'4.CAP_ENDMNT'!B:B,'4.CAP_ENDMNT'!G:G,0,0,1) -> 3662325591 | Y5: =+_xlfn.XLOOKUP(PROYECTOS[[#This Row],[MUNICIPIO]],'4.CAP_ENDMNT'!B:B,'4.CAP_ENDMNT'!H:H,0,0,1) -> 0 | Z5: =+_xlfn.XLOOKUP(PROYECTOS[[#This Row],[MUNICIPIO]],'4.CAP_ENDMNT'!B:B,'4.CAP_ENDMNT'!I:I,0,0,1) -> 3662325591 | AA5: =+_xlfn.XLOOKUP(PROYECTOS[[#This Row],[MUNICIPIO]],'4.CAP_ENDMNT'!B:B,'4.CAP_ENDMNT'!J:J,0,0,1) -> 0.3024434 | AB5: =+_xlfn.XLOOKUP(PROYECTOS[[#This Row],[MUNICIPIO]],'4.CAP_ENDMNT'!B:B,'4.CAP_ENDMNT'!K:K,0,0,1) -> 8.4468017e+09 | AC5: =+_xlfn.XLOOKUP(PROYECTOS[[#This Row],[MUNICIPIO]],'4.CAP_ENDMNT'!B:B,'4.CAP_ENDMNT'!L:L,0,0,1) -> 6.7574414e+09 | AD5: =+_xlfn.XLOOKUP(PROYECTOS[[#This Row],[MUNICIPIO]],'4.CAP_ENDMNT'!B:B,'4.CAP_ENDMNT'!M:M,0,0,1) -> 5.068081e+09 | AE5: =+_xlfn.XLOOKUP(PROYECTOS[[#This Row],[MUNICIPIO]],'4.CAP_ENDMNT'!B:B,'4.CAP_ENDMNT'!N:N,0,0,1) -> 1 | AF5: =+_xlfn.XLOOKUP(PROYECTOS[[#This Row],[MUNICIPIO]],'4.CAP_ENDMNT'!B:B,'4.CAP_ENDMNT'!O:O,0,0,1) -> 0.55253262 | AG5: =+_xlfn.XLOOKUP(PROYECTOS[[#This Row],[MUNICIPIO]],'4.CAP_ENDMNT'!B:B,'4.CAP_ENDMNT'!P:P,0,0,1) -> 0.8 | AH5: =+_xlfn.XLOOKUP(PROYECTOS[[#This Row],[MUNICIPIO]],'4.CAP_ENDMNT'!B:B,'4.CAP_ENDMNT'!Q:Q,0,0,1) -> Cumple | AI5: =+_xlfn.XLOOKUP(PROYECTOS[[#This Row],[MUNICIPIO]],'4.CAP_ENDMNT'!B:B,'4.CAP_ENDMNT'!V:V,0,0,1) -> 1.0136162e+09 | AJ5: =+_xlfn.XLOOKUP(PROYECTOS[[#This Row],[MUNICIPIO]],'4.CAP_ENDMNT'!B:B,'4.CAP_ENDMNT'!Y:Y,0,0,1) -> 5.2816972e+09
A6: 6 | B6: Placa huella Abejorral - Purima | C6: =+_xlfn.XLOOKUP(PROYECTOS[[#This Row],[ID_NECESIDAD]],'1.RADICADOS'!G:G,'1.RADICADOS'!C:C,0,0,1)*1 -> 45341 | D6: Abejorral | E6: =+_xlfn.XLOOKUP(PROYECTOS[[#This Row],[MUNICIPIO]],MUNICIPIOS!A:A,MUNICIPIOS!E:E,0,0,1) -> Oriente | F6: =+_xlfn.XLOOKUP(PROYECTOS[[#This Row],[MUNICIPIO]],MUNICIPIOS!A:A,MUNICIPIOS!F:F,0,0,1) -> -75.428739 | G6: =+_xlfn.XLOOKUP(PROYECTOS[[#This Row],[MUNICIPIO]],MUNICIPIOS!A:A,MUNICIPIOS!G:G,0,0,1) -> 5.789315 | H6: =+_xlfn.XLOOKUP(PROYECTOS[[#This Row],[MUNICIPIO]],MUNICIPIOS!A:A,MUNICIPIOS!B:B,0,0,1) -> 0 | I6: =+_xlfn.XLOOKUP(PROYECTOS[[#This Row],[MUNICIPIO]],MUNICIPIOS!A:A,MUNICIPIOS!C:C,0,0,1) -> 1 | J6: {=_xlfn.TEXTJOIN(" ", TRUE, IF(radicados[ID PROYECTOS]=A6, radicados[RADICADO], ""))} -> 2024010071479 | K6: 1 | M6: Placa huella | N6: Tercer Orden | O6: Vías terciarias mejoradas | P6: No tiene E&D. GOB 50% MUNIC 30% COM 20% | Q6: 1 | R6: SGR Regionales 60% | S6: Placa huellas 2025-2 | T6: =+_xlfn.XLOOKUP(PROYECTOS[[#This Row],[MUNICIPIO]],'4.CAP_ENDMNT'!B:B,'4.CAP_ENDMNT'!C:C,0,0,1) -> 6 | U6: =+_xlfn.XLOOKUP(PROYECTOS[[#This Row],[MUNICIPIO]],'4.CAP_ENDMNT'!B:B,'4.CAP_ENDMNT'!D:D,0,0,1) -> 1.5030771e+10 | V6: =+_xlfn.XLOOKUP(PROYECTOS[[#This Row],[MUNICIPIO]],'4.CAP_ENDMNT'!B:B,'4.CAP_ENDMNT'!E:E,0,0,1) -> 4.4096727e+09 | W6: =+_xlfn.XLOOKUP(PROYECTOS[[#This Row],[MUNICIPIO]],'4.CAP_ENDMNT'!B:B,'4.CAP_ENDMNT'!F:F,0,0,1) -> 1.0621098e+10 | X6: =+_xlfn.XLOOKUP(PROYECTOS[[#This Row],[MUNICIPIO]],'4.CAP_ENDMNT'!B:B,'4.CAP_ENDMNT'!G:G,0,0,1) -> 1969764886 | Y6: =+_xlfn.XLOOKUP(PROYECTOS[[#This Row],[MUNICIPIO]],'4.CAP_ENDMNT'!B:B,'4.CAP_ENDMNT'!H:H,0,0,1) -> 0 | Z6: =+_xlfn.XLOOKUP(PROYECTOS[[#This Row],[MUNICIPIO]],'4.CAP_ENDMNT'!B:B,'4.CAP_ENDMNT'!I:I,0,0,1) -> 1969764886 | AA6: =+_xlfn.XLOOKUP(PROYECTOS[[#This Row],[MUNICIPIO]],'4.CAP_ENDMNT'!B:B,'4.CAP_ENDMNT'!J:J,0,0,1) -> 0.13104883 | AB6: =+_xlfn.XLOOKUP(PROYECTOS[[#This Row],[MUNICIPIO]],'4.CAP_ENDMNT'!B:B,'4.CAP_ENDMNT'!K:K,0,0,1) -> 1.3061006e+10 | AC6: =+_xlfn.XLOOKUP(PROYECTOS[[#This Row],[MUNICIPIO]],'4.CAP_ENDMNT'!B:B,'4.CAP_ENDMNT'!L:L,0,0,1) -> 1.0448805e+10 | AD6: =+_xlfn.XLOOKUP(PROYECTOS[[#This Row],[MUNICIPIO]],'4.CAP_ENDMNT'!B:B,'4.CAP_ENDMNT'!M:M,0,0,1) -> 7.8366036e+09 | AE6: =+_xlfn.XLOOKUP(PROYECTOS[[#This Row],[MUNICIPIO]],'4.CAP_ENDMNT'!B:B,'4.CAP_ENDMNT'!N:N,0,0,1) -> 1 | AF6: =+_xlfn.XLOOKUP(PROYECTOS[[#This Row],[MUNICIPIO]],'4.CAP_ENDMNT'!B:B,'4.CAP_ENDMNT'!O:O,0,0,1) -> 0.39507659 | AG6: =+_xlfn.XLOOKUP(PROYECTOS[[#This Row],[MUNICIPIO]],'4.CAP_ENDMNT'!B:B,'4.CAP_ENDMNT'!P:P,0,0,1) -> 0.8 | AH6: =+_xlfn.XLOOKUP(PROYECTOS[[#This Row],[MUNICIPIO]],'4.CAP_ENDMNT'!B:B,'4.CAP_ENDMNT'!Q:Q,0,0,1) -> Cumple | AI6: =+_xlfn.XLOOKUP(PROYECTOS[[#This Row],[MUNICIPIO]],'4.CAP_ENDMNT'!B:B,'4.CAP_ENDMNT'!V:V,0,0,1) -> 1.5673207e+09 | AJ6: =+_xlfn.XLOOKUP(PROYECTOS[[#This Row],[MUNICIPIO]],'4.CAP_ENDMNT'!B:B,'4.CAP_ENDMNT'!Y:Y,0,0,1) -> 4.2011717e+09
A7: 7 | B7: Pavimentación de 11km de la vía Riogrande - Bellavista (05237VT073) | C7: =+_xlfn.XLOOKUP(PROYECTOS[[#This Row],[ID_NECESIDAD]],'1.RADICADOS'!G:G,'1.RADICADOS'!C:C,0,0,1)*1 -> 45308 | D7: Donmatías | E7: =+_xlfn.XLOOKUP(PROYECTOS[[#This Row],[MUNICIPIO]],MUNICIPIOS!A:A,MUNICIPIOS!E:E,0,0,1) -> Norte | F7: =+_xlfn.XLOOKUP(PROYECTOS[[#This Row],[MUNICIPIO]],MUNICIPIOS!A:A,MUNICIPIOS!F:F,0,0,1) -> -75.39263 | G7: =+_xlfn.XLOOKUP(PROYECTOS[[#This Row],[MUNICIPIO]],MUNICIPIOS!A:A,MUNICIPIOS!G:G,0,0,1) -> 6,485603 | H7: =+_xlfn.XLOOKUP(PROYECTOS[[#This Row],[MUNICIPIO]],MUNICIPIOS!A:A,MUNICIPIOS!B:B,0,0,1) -> 0 | I7: =+_xlfn.XLOOKUP(PROYECTOS[[#This Row],[MUNICIPIO]],MUNICIPIOS!A:A,MUNICIPIOS!C:C,0,0,1) -> 0 | J7: {=_xlfn.TEXTJOIN(" ", TRUE, IF(radicados[ID PROYECTOS]=A7, radicados[RADICADO], ""))} -> 2024010019030 | K7: 1 | M7: Pavimento Flexible | N7: Tercer Orden | O7: Vías terciarias mejoradas | T7: =+_xlfn.XLOOKUP(PROYECTOS[[#This Row],[MUNICIPIO]],'4.CAP_ENDMNT'!B:B,'4.CAP_ENDMNT'!C:C,0,0,1) -> 6 | U7: =+_xlfn.XLOOKUP(PROYECTOS[[#This Row],[MUNICIPIO]],'4.CAP_ENDMNT'!B:B,'4.CAP_ENDMNT'!D:D,0,0,1) -> 2.4529039e+10 | V7: =+_xlfn.XLOOKUP(PROYECTOS[[#This Row],[MUNICIPIO]],'4.CAP_ENDMNT'!B:B,'4.CAP_ENDMNT'!E:E,0,0,1) -> 8.9730124e+09 | W7: =+_xlfn.XLOOKUP(PROYECTOS[[#This Row],[MUNICIPIO]],'4.CAP_ENDMNT'!B:B,'4.CAP_ENDMNT'!F:F,0,0,1) -> 1.5556027e+10 | X7: =+_xlfn.XLOOKUP(PROYECTOS[[#This Row],[MUNICIPIO]],'4.CAP_ENDMNT'!B:B,'4.CAP_ENDMNT'!G:G,0,0,1) -> 7973050390 | Y7: =+_xlfn.XLOOKUP(PROYECTOS[[#This Row],[MUNICIPIO]],'4.CAP_ENDMNT'!B:B,'4.CAP_ENDMNT'!H:H,0,0,1) -> 1625381984 | Z7: =+_xlfn.XLOOKUP(PROYECTOS[[#This Row],[MUNICIPIO]],'4.CAP_ENDMNT'!B:B,'4.CAP_ENDMNT'!I:I,0,0,1) -> 9598432374 | AA7: =+_xlfn.XLOOKUP(PROYECTOS[[#This Row],[MUNICIPIO]],'4.CAP_ENDMNT'!B:B,'4.CAP_ENDMNT'!J:J,0,0,1) -> 0.39130894 | AB7: =+_xlfn.XLOOKUP(PROYECTOS[[#This Row],[MUNICIPIO]],'4.CAP_ENDMNT'!B:B,'4.CAP_ENDMNT'!K:K,0,0,1) -> 1.4930607e+10 | AC7: =+_xlfn.XLOOKUP(PROYECTOS[[#This Row],[MUNICIPIO]],'4.CAP_ENDMNT'!B:B,'4.CAP_ENDMNT'!L:L,0,0,1) -> 1.1944486e+10 | AD7: =+_xlfn.XLOOKUP(PROYECTOS[[#This Row],[MUNICIPIO]],'4.CAP_ENDMNT'!B:B,'4.CAP_ENDMNT'!M:M,0,0,1) -> 8.9583642e+09 | AE7: =+_xlfn.XLOOKUP(PROYECTOS[[#This Row],[MUNICIPIO]],'4.CAP_ENDMNT'!B:B,'4.CAP_ENDMNT'!N:N,0,0,1) -> 0.83066172 | AF7: =+_xlfn.XLOOKUP(PROYECTOS[[#This Row],[MUNICIPIO]],'4.CAP_ENDMNT'!B:B,'4.CAP_ENDMNT'!O:O,0,0,1) -> 0.53024344 | AG7: =+_xlfn.XLOOKUP(PROYECTOS[[#This Row],[MUNICIPIO]],'4.CAP_ENDMNT'!B:B,'4.CAP_ENDMNT'!P:P,0,0,1) -> 0.8 | AH7: =+_xlfn.XLOOKUP(PROYECTOS[[#This Row],[MUNICIPIO]],'4.CAP_ENDMNT'!B:B,'4.CAP_ENDMNT'!Q:Q,0,0,1) -> Cumple | AI7: =+_xlfn.XLOOKUP(PROYECTOS[[#This Row],[MUNICIPIO]],'4.CAP_ENDMNT'!B:B,'4.CAP_ENDMNT'!V:V,0,0,1) -> 1.7916728e+09 | AJ7: =+_xlfn.XLOOKUP(PROYECTOS[[#This Row],[MUNICIPIO]],'4.CAP_ENDMNT'!B:B,'4.CAP_ENDMNT'!Y:Y,0,0,1) -> -8.1641356e+09
A8: 8 | B8: Solicitud de apoyo y acompañamiento integral a la Gestión territorial - Remitido por el ministerio de ambiente | C8: =+_xlfn.XLOOKUP(PROYECTOS[[#This Row],[ID_NECESIDAD]],'1.RADICADOS'!G:G,'1.RADICADOS'!C:C,0,0,1)*1 -> 45308 | D8: Carepa | E8: =+_xlfn.XLOOKUP(PROYECTOS[[#This Row],[MUNICIPIO]],MUNICIPIOS!A:A,MUNICIPIOS!E:E,0,0,1) -> Urabá | F8: =+_xlfn.XLOOKUP(PROYECTOS[[#This Row],[MUNICIPIO]],MUNICIPIOS!A:A,MUNICIPIOS!F:F,0,0,1) -> -76.652652 | G8: =+_xlfn.XLOOKUP(PROYECTOS[[#This Row],[MUNICIPIO]],MUNICIPIOS!A:A,MUNICIPIOS!G:G,0,0,1) -> 7,755148 | H8: =+_xlfn.XLOOKUP(PROYECTOS[[#This Row],[MUNICIPIO]],MUNICIPIOS!A:A,MUNICIPIOS!B:B,0,0,1) -> 1 | I8: =+_xlfn.XLOOKUP(PROYECTOS[[#This Row],[MUNICIPIO]],MUNICIPIOS!A:A,MUNICIPIOS!C:C,0,0,1) -> 1 | J8: {=_xlfn.TEXTJOIN(" ", TRUE, IF(radicados[ID PROYECTOS]=A8, radicados[RADICADO], ""))} -> 2024010020020 | K8: N/A | M8: Otros | N8: N/A | O8: Otros | T8: =+_xlfn.XLOOKUP(PROYECTOS[[#This Row],[MUNICIPIO]],'4.CAP_ENDMNT'!B:B,'4.CAP_ENDMNT'!C:C,0,0,1) -> 6 | U8: =+_xlfn.XLOOKUP(PROYECTOS[[#This Row],[MUNICIPIO]],'4.CAP_ENDMNT'!B:B,'4.CAP_ENDMNT'!D:D,0,0,1) -> 3.1551502e+10 | V8: =+_xlfn.XLOOKUP(PROYECTOS[[#This Row],[MUNICIPIO]],'4.CAP_ENDMNT'!B:B,'4.CAP_ENDMNT'!E:E,0,0,1) -> 1.2896902e+10 | W8: =+_xlfn.XLOOKUP(PROYECTOS[[#This Row],[MUNICIPIO]],'4.CAP_ENDMNT'!B:B,'4.CAP_ENDMNT'!F:F,0,0,1) -> 1.86546e+10 | X8: =+_xlfn.XLOOKUP(PROYECTOS[[#This Row],[MUNICIPIO]],'4.CAP_ENDMNT'!B:B,'4.CAP_ENDMNT'!G:G,0,0,1) -> 4320802475 | Y8: =+_xlfn.XLOOKUP(PROYECTOS[[#This Row],[MUNICIPIO]],'4.CAP_ENDMNT'!B:B,'4.CAP_ENDMNT'!H:H,0,0,1) -> 2.1185629e+09 | Z8: =+_xlfn.XLOOKUP(PROYECTOS[[#This Row],[MUNICIPIO]],'4.CAP_ENDMNT'!B:B,'4.CAP_ENDMNT'!I:I,0,0,1) -> 6.4393654e+09 | AA8: =+_xlfn.XLOOKUP(PROYECTOS[[#This Row],[MUNICIPIO]],'4.CAP_ENDMNT'!B:B,'4.CAP_ENDMNT'!J:J,0,0,1) -> 0.20409062 | AB8: =+_xlfn.XLOOKUP(PROYECTOS[[#This Row],[MUNICIPIO]],'4.CAP_ENDMNT'!B:B,'4.CAP_ENDMNT'!K:K,0,0,1) -> 2.5112136e+10 | AC8: =+_xlfn.XLOOKUP(PROYECTOS[[#This Row],[MUNICIPIO]],'4.CAP_ENDMNT'!B:B,'4.CAP_ENDMNT'!L:L,0,0,1) -> 2.0089709e+10 | AD8: =+_xlfn.XLOOKUP(PROYECTOS[[#This Row],[MUNICIPIO]],'4.CAP_ENDMNT'!B:B,'4.CAP_ENDMNT'!M:M,0,0,1) -> 1.5067282e+10 | AE8: =+_xlfn.XLOOKUP(PROYECTOS[[#This Row],[MUNICIPIO]],'4.CAP_ENDMNT'!B:B,'4.CAP_ENDMNT'!N:N,0,0,1) -> 0.67099818 | AF8: =+_xlfn.XLOOKUP(PROYECTOS[[#This Row],[MUNICIPIO]],'4.CAP_ENDMNT'!B:B,'4.CAP_ENDMNT'!O:O,0,0,1) -> 0.60103296 | AG8: =+_xlfn.XLOOKUP(PROYECTOS[[#This Row],[MUNICIPIO]],'4.CAP_ENDMNT'!B:B,'4.CAP_ENDMNT'!P:P,0,0,1) -> 0.8 | AH8: =+_xlfn.XLOOKUP(PROYECTOS[[#This Row],[MUNICIPIO]],'4.CAP_ENDMNT'!B:B,'4.CAP_ENDMNT'!Q:Q,0,0,1) -> Cumple | AI8: =+_xlfn.XLOOKUP(PROYECTOS[[#This Row],[MUNICIPIO]],'4.CAP_ENDMNT'!B:B,'4.CAP_ENDMNT'!V:V,0,0,1) -> 3.0134564e+09 | AJ8: =+_xlfn.XLOOKUP(PROYECTOS[[#This Row],[MUNICIPIO]],'4.CAP_ENDMNT'!B:B,'4.CAP_ENDMNT'!Y:Y,0,0,1) -> 1.0290789e+10
A9: 9 | B9: Pavimentación de la vía que conduce al corregimiento portachuelo en Amalfí desde el municipio de Vegachí (05858VT61) "Alejandría - Cascajo" | C9: =+_xlfn.XLOOKUP(PROYECTOS[[#This Row],[ID_NECESIDAD]],'1.RADICADOS'!G:G,'1.RADICADOS'!C:C,0,0,1)*1 -> 45414 | D9: Vegachí | E9: =+_xlfn.XLOOKUP(PROYECTOS[[#This Row],[MUNICIPIO]],MUNICIPIOS!A:A,MUNICIPIOS!E:E,0,0,1) -> Nordeste | F9: =+_xlfn.XLOOKUP(PROYECTOS[[#This Row],[MUNICIPIO]],MUNICIPIOS!A:A,MUNICIPIOS!F:F,0,0,1) -> -74.798714 | G9: =+_xlfn.XLOOKUP(PROYECTOS[[#This Row],[MUNICIPIO]],MUNICIPIOS!A:A,MUNICIPIOS!G:G,0,0,1) -> 6.773525 | H9: =+_xlfn.XLOOKUP(PROYECTOS[[#This Row],[MUNICIPIO]],MUNICIPIOS!A:A,MUNICIPIOS!B:B,0,0,1) -> 0 | I9: =+_xlfn.XLOOKUP(PROYECTOS[[#This Row],[MUNICIPIO]],MUNICIPIOS!A:A,MUNICIPIOS!C:C,0,0,1) -> 1 | J9: {=_xlfn.TEXTJOIN(" ", TRUE, IF(radicados[ID PROYECTOS]=A9, radicados[RADICADO], ""))} -> 2024010048752 | K9: 1 | M9: Pavimento Flexible | N9: Tercer Orden | O9: Vías terciarias mejoradas | T9: =+_xlfn.XLOOKUP(PROYECTOS[[#This Row],[MUNICIPIO]],'4.CAP_ENDMNT'!B:B,'4.CAP_ENDMNT'!C:C,0,0,1) -> 6 | U9: =+_xlfn.XLOOKUP(PROYECTOS[[#This Row],[MUNICIPIO]],'4.CAP_ENDMNT'!B:B,'4.CAP_ENDMNT'!D:D,0,0,1) -> 1.4438256e+10 | V9: =+_xlfn.XLOOKUP(PROYECTOS[[#This Row],[MUNICIPIO]],'4.CAP_ENDMNT'!B:B,'4.CAP_ENDMNT'!E:E,0,0,1) -> 4.6682009e+09 | W9: =+_xlfn.XLOOKUP(PROYECTOS[[#This Row],[MUNICIPIO]],'4.CAP_ENDMNT'!B:B,'4.CAP_ENDMNT'!F:F,0,0,1) -> 9.770055e+09 | X9: =+_xlfn.XLOOKUP(PROYECTOS[[#This Row],[MUNICIPIO]],'4.CAP_ENDMNT'!B:B,'4.CAP_ENDMNT'!G:G,0,0,1) -> 2534414723 | Y9: =+_xlfn.XLOOKUP(PROYECTOS[[#This Row],[MUNICIPIO]],'4.CAP_ENDMNT'!B:B,'4.CAP_ENDMNT'!H:H,0,0,1) -> 0 | Z9: =+_xlfn.XLOOKUP(PROYECTOS[[#This Row],[MUNICIPIO]],'4.CAP_ENDMNT'!B:B,'4.CAP_ENDMNT'!I:I,0,0,1) -> 2534414723 | AA9: =+_xlfn.XLOOKUP(PROYECTOS[[#This Row],[MUNICIPIO]],'4.CAP_ENDMNT'!B:B,'4.CAP_ENDMNT'!J:J,0,0,1) -> 0.17553469 | AB9: =+_xlfn.XLOOKUP(PROYECTOS[[#This Row],[MUNICIPIO]],'4.CAP_ENDMNT'!B:B,'4.CAP_ENDMNT'!K:K,0,0,1) -> 1.1903841e+10 | AC9: =+_xlfn.XLOOKUP(PROYECTOS[[#This Row],[MUNICIPIO]],'4.CAP_ENDMNT'!B:B,'4.CAP_ENDMNT'!L:L,0,0,1) -> 9.523073e+09 | AD9: =+_xlfn.XLOOKUP(PROYECTOS[[#This Row],[MUNICIPIO]],'4.CAP_ENDMNT'!B:B,'4.CAP_ENDMNT'!M:M,0,0,1) -> 7.1423047e+09 | AE9: =+_xlfn.XLOOKUP(PROYECTOS[[#This Row],[MUNICIPIO]],'4.CAP_ENDMNT'!B:B,'4.CAP_ENDMNT'!N:N,0,0,1) -> 1 | AF9: =+_xlfn.XLOOKUP(PROYECTOS[[#This Row],[MUNICIPIO]],'4.CAP_ENDMNT'!B:B,'4.CAP_ENDMNT'!O:O,0,0,1) -> 0.51487078 | AG9: =+_xlfn.XLOOKUP(PROYECTOS[[#This Row],[MUNICIPIO]],'4.CAP_ENDMNT'!B:B,'4.CAP_ENDMNT'!P:P,0,0,1) -> 0.8 | AH9: =+_xlfn.XLOOKUP(PROYECTOS[[#This Row],[MUNICIPIO]],'4.CAP_ENDMNT'!B:B,'4.CAP_ENDMNT'!Q:Q,0,0,1) -> Cumple | AI9: =+_xlfn.XLOOKUP(PROYECTOS[[#This Row],[MUNICIPIO]],'4.CAP_ENDMNT'!B:B,'4.CAP_ENDMNT'!V:V,0,0,1) -> 1.4284609e+09 | AJ9: =+_xlfn.XLOOKUP(PROYECTOS[[#This Row],[MUNICIPIO]],'4.CAP_ENDMNT'!B:B,'4.CAP_ENDMNT'!Y:Y,0,0,1) -> 1.1007549e+09
A10: 10 | B10: Propuesta proyectos en desarrollo Bajo Cauca Antioqueño. Finca la Mariela - Caucasía Antioquia | C10: =+_xlfn.XLOOKUP(PROYECTOS[[#This Row],[ID_NECESIDAD]],'1.RADICADOS'!G:G,'1.RADICADOS'!C:C,0,0,1)*1 -> 45293 | D10: Caucasia | E10: =+_xlfn.XLOOKUP(PROYECTOS[[#This Row],[MUNICIPIO]],MUNICIPIOS!A:A,MUNICIPIOS!E:E,0,0,1) -> Bajo Cauca | F10: =+_xlfn.XLOOKUP(PROYECTOS[[#This Row],[MUNICIPIO]],MUNICIPIOS!A:A,MUNICIPIOS!F:F,0,0,1) -> -75.197996 | G10: =+_xlfn.XLOOKUP(PROYECTOS[[#This Row],[MUNICIPIO]],MUNICIPIOS!A:A,MUNICIPIOS!G:G,0,0,1) -> 7,977278 | H10: =+_xlfn.XLOOKUP(PROYECTOS[[#This Row],[MUNICIPIO]],MUNICIPIOS!A:A,MUNICIPIOS!B:B,0,0,1) -> 1 | I10: =+_xlfn.XLOOKUP(PROYECTOS[[#This Row],[MUNICIPIO]],MUNICIPIOS!A:A,MUNICIPIOS!C:C,0,0,1) -> 1 | J10: {=_xlfn.TEXTJOIN(" ", TRUE, IF(radicados[ID PROYECTOS]=A10, radicados[RADICADO], ""))} -> 2024010043395 | K10: 2 | M10: Parque | N10: N/A | O10: Espacio público adecuado | P10: Son tres proyectos para los cuales CEDRA busca apoyo | T10: =+_xlfn.XLOOKUP(PROYECTOS[[#This Row],[MUNICIPIO]],'4.CAP_ENDMNT'!B:B,'4.CAP_ENDMNT'!C:C,0,0,1) -> 5 | U10: =+_xlfn.XLOOKUP(PROYECTOS[[#This Row],[MUNICIPIO]],'4.CAP_ENDMNT'!B:B,'4.CAP_ENDMNT'!D:D,0,0,1) -> 5.5415011e+10 | V10: =+_xlfn.XLOOKUP(PROYECTOS[[#This Row],[MUNICIPIO]],'4.CAP_ENDMNT'!B:B,'4.CAP_ENDMNT'!E:E,0,0,1) -> 2.4252117e+10 | W10: =+_xlfn.XLOOKUP(PROYECTOS[[#This Row],[MUNICIPIO]],'4.CAP_ENDMNT'!B:B,'4.CAP_ENDMNT'!F:F,0,0,1) -> 3.1162894e+10 | X10: =+_xlfn.XLOOKUP(PROYECTOS[[#This Row],[MUNICIPIO]],'4.CAP_ENDMNT'!B:B,'4.CAP_ENDMNT'!G:G,0,0,1) -> 8970758412 | Y10: =+_xlfn.XLOOKUP(PROYECTOS[[#This Row],[MUNICIPIO]],'4.CAP_ENDMNT'!B:B,'4.CAP_ENDMNT'!H:H,0,0,1) -> 3.5721739e+09 | Z10: =+_xlfn.XLOOKUP(PROYECTOS[[#This Row],[MUNICIPIO]],'4.CAP_ENDMNT'!B:B,'4.CAP_ENDMNT'!I:I,0,0,1) -> 1.2542932e+10 | AA10: =+_xlfn.XLOOKUP(PROYECTOS[[#This Row],[MUNICIPIO]],'4.CAP_ENDMNT'!B:B,'4.CAP_ENDMNT'!J:J,0,0,1) -> 0.22634539 | AB10: =+_xlfn.XLOOKUP(PROYECTOS[[#This Row],[MUNICIPIO]],'4.CAP_ENDMNT'!B:B,'4.CAP_ENDMNT'!K:K,0,0,1) -> 4.2872079e+10 | AC10: =+_xlfn.XLOOKUP(PROYECTOS[[#This Row],[MUNICIPIO]],'4.CAP_ENDMNT'!B:B,'4.CAP_ENDMNT'!L:L,0,0,1) -> 3.4297663e+10 | AD10: =+_xlfn.XLOOKUP(PROYECTOS[[#This Row],[MUNICIPIO]],'4.CAP_ENDMNT'!B:B,'4.CAP_ENDMNT'!M:M,0,0,1) -> 2.5723247e+10 | AE10: =+_xlfn.XLOOKUP(PROYECTOS[[#This Row],[MUNICIPIO]],'4.CAP_ENDMNT'!B:B,'4.CAP_ENDMNT'!N:N,0,0,1) -> 0.71520425 | AF10: =+_xlfn.XLOOKUP(PROYECTOS[[#This Row],[MUNICIPIO]],'4.CAP_ENDMNT'!B:B,'4.CAP_ENDMNT'!O:O,0,0,1) -> 0.67052011 | AG10: =+_xlfn.XLOOKUP(PROYECTOS[[#This Row],[MUNICIPIO]],'4.CAP_ENDMNT'!B:B,'4.CAP_ENDMNT'!P:P,0,0,1) -> 0.8 | AH10: =+_xlfn.XLOOKUP(PROYECTOS[[#This Row],[MUNICIPIO]],'4.CAP_ENDMNT'!B:B,'4.CAP_ENDMNT'!Q:Q,0,0,1) -> Cumple | AI10: =+_xlfn.XLOOKUP(PROYECTOS[[#This Row],[MUNICIPIO]],'4.CAP_ENDMNT'!B:B,'4.CAP_ENDMNT'!V:V,0,0,1) -> 5.1446495e+09 | AJ10: =+_xlfn.XLOOKUP(PROYECTOS[[#This Row],[MUNICIPIO]],'4.CAP_ENDMNT'!B:B,'4.CAP_ENDMNT'!Y:Y,0,0,1) -> 3.549127e+09
A11: 11 | B11: Recuperación pavimentación y mantenimiento a la malla vial que comunica al municipio de Armenia con el municipio de Titiribí | C11: =+_xlfn.XLOOKUP(PROYECTOS[[#This Row],[ID_NECESIDAD]],'1.RADICADOS'!G:G,'1.RADICADOS'!C:C,0,0,1)*1 -> 45338 | D11: Armenia | E11: =+_xlfn.XLOOKUP(PROYECTOS[[#This Row],[MUNICIPIO]],MUNICIPIOS!A:A,MUNICIPIOS!E:E,0,0,1) -> Occidente | F11: =+_xlfn.XLOOKUP(PROYECTOS[[#This Row],[MUNICIPIO]],MUNICIPIOS!A:A,MUNICIPIOS!F:F,0,0,1) -> -75.786647 | G11: =+_xlfn.XLOOKUP(PROYECTOS[[#This Row],[MUNICIPIO]],MUNICIPIOS!A:A,MUNICIPIOS!G:G,0,0,1) -> 6,155667 | H11: =+_xlfn.XLOOKUP(PROYECTOS[[#This Row],[MUNICIPIO]],MUNICIPIOS!A:A,MUNICIPIOS!B:B,0,0,1) -> 0 | I11: =+_xlfn.XLOOKUP(PROYECTOS[[#This Row],[MUNICIPIO]],MUNICIPIOS!A:A,MUNICIPIOS!C:C,0,0,1) -> 0 | J11: {=_xlfn.TEXTJOIN(" ", TRUE, IF(radicados[ID PROYECTOS]=A11, radicados[RADICADO], ""))} -> 2024010068835 | K11: 1 | M11: Pavimento Flexible | N11: Tercer Orden | O11: Vías terciarias mejoradas | T11: =+_xlfn.XLOOKUP(PROYECTOS[[#This Row],[MUNICIPIO]],'4.CAP_ENDMNT'!B:B,'4.CAP_ENDMNT'!C:C,0,0,1) -> 6 | U11: =+_xlfn.XLOOKUP(PROYECTOS[[#This Row],[MUNICIPIO]],'4.CAP_ENDMNT'!B:B,'4.CAP_ENDMNT'!D:D,0,0,1) -> 4.6679398e+09 | V11: =+_xlfn.XLOOKUP(PROYECTOS[[#This Row],[MUNICIPIO]],'4.CAP_ENDMNT'!B:B,'4.CAP_ENDMNT'!E:E,0,0,1) -> 2.0296029e+09 | W11: =+_xlfn.XLOOKUP(PROYECTOS[[#This Row],[MUNICIPIO]],'4.CAP_ENDMNT'!B:B,'4.CAP_ENDMNT'!F:F,0,0,1) -> 2.6383368e+09 | X11: =+_xlfn.XLOOKUP(PROYECTOS[[#This Row],[MUNICIPIO]],'4.CAP_ENDMNT'!B:B,'4.CAP_ENDMNT'!G:G,0,0,1) -> 355713183 | Y11: =+_xlfn.XLOOKUP(PROYECTOS[[#This Row],[MUNICIPIO]],'4.CAP_ENDMNT'!B:B,'4.CAP_ENDMNT'!H:H,0,0,1) -> 0 | Z11: =+_xlfn.XLOOKUP(PROYECTOS[[#This Row],[MUNICIPIO]],'4.CAP_ENDMNT'!B:B,'4.CAP_ENDMNT'!I:I,0,0,1) -> 355713183 | AA11: =+_xlfn.XLOOKUP(PROYECTOS[[#This Row],[MUNICIPIO]],'4.CAP_ENDMNT'!B:B,'4.CAP_ENDMNT'!J:J,0,0,1) -> 0.076203464 | AB11: =+_xlfn.XLOOKUP(PROYECTOS[[#This Row],[MUNICIPIO]],'4.CAP_ENDMNT'!B:B,'4.CAP_ENDMNT'!K:K,0,0,1) -> 4.3122266e+09 | AC11: =+_xlfn.XLOOKUP(PROYECTOS[[#This Row],[MUNICIPIO]],'4.CAP_ENDMNT'!B:B,'4.CAP_ENDMNT'!L:L,0,0,1) -> 3.4497813e+09 | AD11: =+_xlfn.XLOOKUP(PROYECTOS[[#This Row],[MUNICIPIO]],'4.CAP_ENDMNT'!B:B,'4.CAP_ENDMNT'!M:M,0,0,1) -> 2.587336e+09 | AE11: =+_xlfn.XLOOKUP(PROYECTOS[[#This Row],[MUNICIPIO]],'4.CAP_ENDMNT'!B:B,'4.CAP_ENDMNT'!N:N,0,0,1) -> 1 | AF11: =+_xlfn.XLOOKUP(PROYECTOS[[#This Row],[MUNICIPIO]],'4.CAP_ENDMNT'!B:B,'4.CAP_ENDMNT'!O:O,0,0,1) -> 0.65637282 | AG11: =+_xlfn.XLOOKUP(PROYECTOS[[#This Row],[MUNICIPIO]],'4.CAP_ENDMNT'!B:B,'4.CAP_ENDMNT'!P:P,0,0,1) -> 0.8 | AH11: =+_xlfn.XLOOKUP(PROYECTOS[[#This Row],[MUNICIPIO]],'4.CAP_ENDMNT'!B:B,'4.CAP_ENDMNT'!Q:Q,0,0,1) -> Cumple | AI11: =+_xlfn.XLOOKUP(PROYECTOS[[#This Row],[MUNICIPIO]],'4.CAP_ENDMNT'!B:B,'4.CAP_ENDMNT'!V:V,0,0,1) -> 5.1746719e+08 | AJ11: =+_xlfn.XLOOKUP(PROYECTOS[[#This Row],[MUNICIPIO]],'4.CAP_ENDMNT'!B:B,'4.CAP_ENDMNT'!Y:Y,0,0,1) -> 3.1048031e+09
A12: 13 | B12: Vía entre corregimiento de San Pablo y vereda Naranjal (Codigo 05856VT104) | C12: 45292 | D12: Támesis | E12: =+_xlfn.XLOOKUP(PROYECTOS[[#This Row],[MUNICIPIO]],MUNICIPIOS!A:A,MUNICIPIOS!E:E,0,0,1) -> Suroeste | F12: =+_xlfn.XLOOKUP(PROYECTOS[[#This Row],[MUNICIPIO]],MUNICIPIOS!A:A,MUNICIPIOS!F:F,0,0,1) -> -75.714429 | G12: =+_xlfn.XLOOKUP(PROYECTOS[[#This Row],[MUNICIPIO]],MUNICIPIOS!A:A,MUNICIPIOS!G:G,0,0,1) -> 5.664645 | H12: =+_xlfn.XLOOKUP(PROYECTOS[[#This Row],[MUNICIPIO]],MUNICIPIOS!A:A,MUNICIPIOS!B:B,0,0,1) -> 0 | I12: =+_xlfn.XLOOKUP(PROYECTOS[[#This Row],[MUNICIPIO]],MUNICIPIOS!A:A,MUNICIPIOS!C:C,0,0,1) -> 0 | J12: {=_xlfn.TEXTJOIN(" ", TRUE, IF(radicados[ID PROYECTOS]=A12, radicados[RADICADO], ""))} | K12: 1 | M12: Placa huella | N12: Tercer Orden | O12: Vías terciarias mejoradas | P12: Via 2.5km que comunica corregimientos de San Pablo y la vereda el Narajal. FASE 1 | T12: =+_xlfn.XLOOKUP(PROYECTOS[[#This Row],[MUNICIPIO]],'4.CAP_ENDMNT'!B:B,'4.CAP_ENDMNT'!C:C,0,0,1) -> 6 | U12: =+_xlfn.XLOOKUP(PROYECTOS[[#This Row],[MUNICIPIO]],'4.CAP_ENDMNT'!B:B,'4.CAP_ENDMNT'!D:D,0,0,1) -> 1.3939578e+10 | V12: =+_xlfn.XLOOKUP(PROYECTOS[[#This Row],[MUNICIPIO]],'4.CAP_ENDMNT'!B:B,'4.CAP_ENDMNT'!E:E,0,0,1) -> 5.4086452e+09 | W12: =+_xlfn.XLOOKUP(PROYECTOS[[#This Row],[MUNICIPIO]],'4.CAP_ENDMNT'!B:B,'4.CAP_ENDMNT'!F:F,0,0,1) -> 8.5309327e+09 | X12: =+_xlfn.XLOOKUP(PROYECTOS[[#This Row],[MUNICIPIO]],'4.CAP_ENDMNT'!B:B,'4.CAP_ENDMNT'!G:G,0,0,1) -> 2408239973 | Y12: =+_xlfn.XLOOKUP(PROYECTOS[[#This Row],[MUNICIPIO]],'4.CAP_ENDMNT'!B:B,'4.CAP_ENDMNT'!H:H,0,0,1) -> 812109375 | Z12: =+_xlfn.XLOOKUP(PROYECTOS[[#This Row],[MUNICIPIO]],'4.CAP_ENDMNT'!B:B,'4.CAP_ENDMNT'!I:I,0,0,1) -> 3220349348 | AA12: =+_xlfn.XLOOKUP(PROYECTOS[[#This Row],[MUNICIPIO]],'4.CAP_ENDMNT'!B:B,'4.CAP_ENDMNT'!J:J,0,0,1) -> 0.23102201 | AB12: =+_xlfn.XLOOKUP(PROYECTOS[[#This Row],[MUNICIPIO]],'4.CAP_ENDMNT'!B:B,'4.CAP_ENDMNT'!K:K,0,0,1) -> 1.0719229e+10 | AC12: =+_xlfn.XLOOKUP(PROYECTOS[[#This Row],[MUNICIPIO]],'4.CAP_ENDMNT'!B:B,'4.CAP_ENDMNT'!L:L,0,0,1) -> 8.5753828e+09 | AD12: =+_xlfn.XLOOKUP(PROYECTOS[[#This Row],[MUNICIPIO]],'4.CAP_ENDMNT'!B:B,'4.CAP_ENDMNT'!M:M,0,0,1) -> 6.4315371e+09 | AE12: =+_xlfn.XLOOKUP(PROYECTOS[[#This Row],[MUNICIPIO]],'4.CAP_ENDMNT'!B:B,'4.CAP_ENDMNT'!N:N,0,0,1) -> 0.74781948 | AF12: =+_xlfn.XLOOKUP(PROYECTOS[[#This Row],[MUNICIPIO]],'4.CAP_ENDMNT'!B:B,'4.CAP_ENDMNT'!O:O,0,0,1) -> 0.4814897 | AG12: =+_xlfn.XLOOKUP(PROYECTOS[[#This Row],[MUNICIPIO]],'4.CAP_ENDMNT'!B:B,'4.CAP_ENDMNT'!P:P,0,0,1) -> 0.8 | AH12: =+_xlfn.XLOOKUP(PROYECTOS[[#This Row],[MUNICIPIO]],'4.CAP_ENDMNT'!B:B,'4.CAP_ENDMNT'!Q:Q,0,0,1) -> Cumple | AI12: =+_xlfn.XLOOKUP(PROYECTOS[[#This Row],[MUNICIPIO]],'4.CAP_ENDMNT'!B:B,'4.CAP_ENDMNT'!V:V,0,0,1) -> 1.2863074e+09 | AJ12: =+_xlfn.XLOOKUP(PROYECTOS[[#This Row],[MUNICIPIO]],'4.CAP_ENDMNT'!B:B,'4.CAP_ENDMNT'!Y:Y,0,0,1) -> -1.0772172e+10
A13: 14 | B13: Solicitud de Pavimentación vía Peñalisa - La Bodega - Tarso La Bodega - Pueblorico con codigo 25BAN03-1 | C13: =+_xlfn.XLOOKUP(PROYECTOS[[#This Row],[ID_NECESIDAD]],'1.RADICADOS'!G:G,'1.RADICADOS'!C:C,0,0,1)*1 -> 45348 | D13: Tarso | E13: =+_xlfn.XLOOKUP(PROYECTOS[[#This Row],[MUNICIPIO]],MUNICIPIOS!A:A,MUNICIPIOS!E:E,0,0,1) -> Suroeste | F13: =+_xlfn.XLOOKUP(PROYECTOS[[#This Row],[MUNICIPIO]],MUNICIPIOS!A:A,MUNICIPIOS!F:F,0,0,1) -> -75.822956 | G13: =+_xlfn.XLOOKUP(PROYECTOS[[#This Row],[MUNICIPIO]],MUNICIPIOS!A:A,MUNICIPIOS!G:G,0,0,1) -> 5.864542 | H13: =+_xlfn.XLOOKUP(PROYECTOS[[#This Row],[MUNICIPIO]],MUNICIPIOS!A:A,MUNICIPIOS!B:B,0,0,1) -> 0 | I13: =+_xlfn.XLOOKUP(PROYECTOS[[#This Row],[MUNICIPIO]],MUNICIPIOS!A:A,MUNICIPIOS!C:C,0,0,1) -> 0 | J13: {=_xlfn.TEXTJOIN(" ", TRUE, IF(radicados[ID PROYECTOS]=A13, radicados[RADICADO], ""))} -> 2024010084216 | K13: 2 | M13: Pavimento Flexible | N13: Segundo Orden | O13: Vías secundarias mejoradas | P13: Peticion se ha hecho en multiples ocasiones. Reclaman un intervencion que nunca se hizo y piden apoyo | T13: =+_xlfn.XLOOKUP(PROYECTOS[[#This Row],[MUNICIPIO]],'4.CAP_ENDMNT'!B:B,'4.CAP_ENDMNT'!C:C,0,0,1) -> 6 | U13: =+_xlfn.XLOOKUP(PROYECTOS[[#This Row],[MUNICIPIO]],'4.CAP_ENDMNT'!B:B,'4.CAP_ENDMNT'!D:D,0,0,1) -> 9.2972046e+09 | V13: =+_xlfn.XLOOKUP(PROYECTOS[[#This Row],[MUNICIPIO]],'4.CAP_ENDMNT'!B:B,'4.CAP_ENDMNT'!E:E,0,0,1) -> 4.6509009e+09 | W13: =+_xlfn.XLOOKUP(PROYECTOS[[#This Row],[MUNICIPIO]],'4.CAP_ENDMNT'!B:B,'4.CAP_ENDMNT'!F:F,0,0,1) -> 4.6463037e+09 | X13: =+_xlfn.XLOOKUP(PROYECTOS[[#This Row],[MUNICIPIO]],'4.CAP_ENDMNT'!B:B,'4.CAP_ENDMNT'!G:G,0,0,1) -> 1308996768 | Y13: =+_xlfn.XLOOKUP(PROYECTOS[[#This Row],[MUNICIPIO]],'4.CAP_ENDMNT'!B:B,'4.CAP_ENDMNT'!H:H,0,0,1) -> 0 | Z13: =+_xlfn.XLOOKUP(PROYECTOS[[#This Row],[MUNICIPIO]],'4.CAP_ENDMNT'!B:B,'4.CAP_ENDMNT'!I:I,0,0,1) -> 1308996768 | AA13: =+_xlfn.XLOOKUP(PROYECTOS[[#This Row],[MUNICIPIO]],'4.CAP_ENDMNT'!B:B,'4.CAP_ENDMNT'!J:J,0,0,1) -> 0.14079466 | AB13: =+_xlfn.XLOOKUP(PROYECTOS[[#This Row],[MUNICIPIO]],'4.CAP_ENDMNT'!B:B,'4.CAP_ENDMNT'!K:K,0,0,1) -> 7.9882078e+09 | AC13: =+_xlfn.XLOOKUP(PROYECTOS[[#This Row],[MUNICIPIO]],'4.CAP_ENDMNT'!B:B,'4.CAP_ENDMNT'!L:L,0,0,1) -> 6.3905663e+09 | AD13: =+_xlfn.XLOOKUP(PROYECTOS[[#This Row],[MUNICIPIO]],'4.CAP_ENDMNT'!B:B,'4.CAP_ENDMNT'!M:M,0,0,1) -> 4.7929247e+09 | AE13: =+_xlfn.XLOOKUP(PROYECTOS[[#This Row],[MUNICIPIO]],'4.CAP_ENDMNT'!B:B,'4.CAP_ENDMNT'!N:N,0,0,1) -> 1 | AF13: =+_xlfn.XLOOKUP(PROYECTOS[[#This Row],[MUNICIPIO]],'4.CAP_ENDMNT'!B:B,'4.CAP_ENDMNT'!O:O,0,0,1) -> 0.67267671 | AG13: =+_xlfn.XLOOKUP(PROYECTOS[[#This Row],[MUNICIPIO]],'4.CAP_ENDMNT'!B:B,'4.CAP_ENDMNT'!P:P,0,0,1) -> 0.8 | AH13: =+_xlfn.XLOOKUP(PROYECTOS[[#This Row],[MUNICIPIO]],'4.CAP_ENDMNT'!B:B,'4.CAP_ENDMNT'!Q:Q,0,0,1) -> Cumple | AI13: =+_xlfn.XLOOKUP(PROYECTOS[[#This Row],[MUNICIPIO]],'4.CAP_ENDMNT'!B:B,'4.CAP_ENDMNT'!V:V,0,0,1) -> 9.5858494e+08 | AJ13: =+_xlfn.XLOOKUP(PROYECTOS[[#This Row],[MUNICIPIO]],'4.CAP_ENDMNT'!B:B,'4.CAP_ENDMNT'!Y:Y,0,0,1) -> -1.2177885e+09
A14: 15 | B14: Mejoramiento de la red vial urbana Municipio de San josé de la Montaña | C14: =+_xlfn.XLOOKUP(PROYECTOS[[#This Row],[ID_NECESIDAD]],'1.RADICADOS'!G:G,'1.RADICADOS'!C:C,0,0,1)*1 -> 45322 | D14: San José de la Montaña | E14: =+_xlfn.XLOOKUP(PROYECTOS[[#This Row],[MUNICIPIO]],MUNICIPIOS!A:A,MUNICIPIOS!E:E,0,0,1) -> Norte | F14: =+_xlfn.XLOOKUP(PROYECTOS[[#This Row],[MUNICIPIO]],MUNICIPIOS!A:A,MUNICIPIOS!F:F,0,0,1) -> -75.683352 | G14: =+_xlfn.XLOOKUP(PROYECTOS[[#This Row],[MUNICIPIO]],MUNICIPIOS!A:A,MUNICIPIOS!G:G,0,0,1) -> 6,85009 | H14: =+_xlfn.XLOOKUP(PROYECTOS[[#This Row],[MUNICIPIO]],MUNICIPIOS!A:A,MUNICIPIOS!B:B,0,0,1) -> 0 | I14: =+_xlfn.XLOOKUP(PROYECTOS[[#This Row],[MUNICIPIO]],MUNICIPIOS!A:A,MUNICIPIOS!C:C,0,0,1) -> 0 | J14: {=_xlfn.TEXTJOIN(" ", TRUE, IF(radicados[ID PROYECTOS]=A14, radicados[RADICADO], ""))} -> 2024010041849 | K14: 1 | M14: Pavimento Flexible | N14: Urbana | O14: Vía urbana mejorada | T14: =+_xlfn.XLOOKUP(PROYECTOS[[#This Row],[MUNICIPIO]],'4.CAP_ENDMNT'!B:B,'4.CAP_ENDMNT'!C:C,0,0,1) -> 6 | U14: =+_xlfn.XLOOKUP(PROYECTOS[[#This Row],[MUNICIPIO]],'4.CAP_ENDMNT'!B:B,'4.CAP_ENDMNT'!D:D,0,0,1) -> 5.4378026e+09 | V14: =+_xlfn.XLOOKUP(PROYECTOS[[#This Row],[MUNICIPIO]],'4.CAP_ENDMNT'!B:B,'4.CAP_ENDMNT'!E:E,0,0,1) -> 2.1952578e+09 | W14: =+_xlfn.XLOOKUP(PROYECTOS[[#This Row],[MUNICIPIO]],'4.CAP_ENDMNT'!B:B,'4.CAP_ENDMNT'!F:F,0,0,1) -> 3.2425447e+09 | X14: =+_xlfn.XLOOKUP(PROYECTOS[[#This Row],[MUNICIPIO]],'4.CAP_ENDMNT'!B:B,'4.CAP_ENDMNT'!G:G,0,0,1) -> 1389038990 | Y14: =+_xlfn.XLOOKUP(PROYECTOS[[#This Row],[MUNICIPIO]],'4.CAP_ENDMNT'!B:B,'4.CAP_ENDMNT'!H:H,0,0,1) -> 0 | Z14: =+_xlfn.XLOOKUP(PROYECTOS[[#This Row],[MUNICIPIO]],'4.CAP_ENDMNT'!B:B,'4.CAP_ENDMNT'!I:I,0,0,1) -> 1389038990 | AA14: =+_xlfn.XLOOKUP(PROYECTOS[[#This Row],[MUNICIPIO]],'4.CAP_ENDMNT'!B:B,'4.CAP_ENDMNT'!J:J,0,0,1) -> 0.25544123 | AB14: =+_xlfn.XLOOKUP(PROYECTOS[[#This Row],[MUNICIPIO]],'4.CAP_ENDMNT'!B:B,'4.CAP_ENDMNT'!K:K,0,0,1) -> 4.0487636e+09 | AC14: =+_xlfn.XLOOKUP(PROYECTOS[[#This Row],[MUNICIPIO]],'4.CAP_ENDMNT'!B:B,'4.CAP_ENDMNT'!L:L,0,0,1) -> 3.2390109e+09 | AD14: =+_xlfn.XLOOKUP(PROYECTOS[[#This Row],[MUNICIPIO]],'4.CAP_ENDMNT'!B:B,'4.CAP_ENDMNT'!M:M,0,0,1) -> 2.4292581e+09 | AE14: =+_xlfn.XLOOKUP(PROYECTOS[[#This Row],[MUNICIPIO]],'4.CAP_ENDMNT'!B:B,'4.CAP_ENDMNT'!N:N,0,0,1) -> 1 | AF14: =+_xlfn.XLOOKUP(PROYECTOS[[#This Row],[MUNICIPIO]],'4.CAP_ENDMNT'!B:B,'4.CAP_ENDMNT'!O:O,0,0,1) -> 0.7423058 | AG14: =+_xlfn.XLOOKUP(PROYECTOS[[#This Row],[MUNICIPIO]],'4.CAP_ENDMNT'!B:B,'4.CAP_ENDMNT'!P:P,0,0,1) -> 0.8 | AH14: =+_xlfn.XLOOKUP(PROYECTOS[[#This Row],[MUNICIPIO]],'4.CAP_ENDMNT'!B:B,'4.CAP_ENDMNT'!Q:Q,0,0,1) -> Cumple | AI14: =+_xlfn.XLOOKUP(PROYECTOS[[#This Row],[MUNICIPIO]],'4.CAP_ENDMNT'!B:B,'4.CAP_ENDMNT'!V:V,0,0,1) -> 4.8585163e+08 | AJ14: =+_xlfn.XLOOKUP(PROYECTOS[[#This Row],[MUNICIPIO]],'4.CAP_ENDMNT'!B:B,'4.CAP_ENDMNT'!Y:Y,0,0,1) -> -1.4155937e+10
